<sdf version='1.7'>
  <world name='default'>
    <light name='sun' type='directional'>
      <cast_shadows>1</cast_shadows>
      <pose>0 0 10 0 -0 0</pose>
      <diffuse>0.8 0.8 0.8 1</diffuse>
      <specular>0.2 0.2 0.2 1</specular>
      <attenuation>
        <range>1000</range>
        <constant>0.9</constant>
        <linear>0.01</linear>
        <quadratic>0.001</quadratic>
      </attenuation>
      <direction>-0.5 0.1 -0.9</direction>
      <spot>
        <inner_angle>0</inner_angle>
        <outer_angle>0</outer_angle>
        <falloff>0</falloff>
      </spot>
    </light>
    <model name='ground_plane'>
      <static>1</static>
      <link name='link'>
        <collision name='collision'>
          <geometry>
            <plane>
              <normal>0 0 1</normal>
              <size>100 100</size>
            </plane>
          </geometry>
          <surface>
            <contact>
              <collide_bitmask>65535</collide_bitmask>
              <ode/>
            </contact>
            <friction>
              <ode>
                <mu>100</mu>
                <mu2>50</mu2>
              </ode>
              <torsional>
                <ode/>
              </torsional>
            </friction>
            <bounce/>
          </surface>
          <max_contacts>10</max_contacts>
        </collision>
        <visual name='visual'>
          <cast_shadows>0</cast_shadows>
          <geometry>
            <plane>
              <normal>0 0 1</normal>
              <size>100 100</size>
            </plane>
          </geometry>
          <material>
            <script>
              <uri>file://media/materials/scripts/gazebo.material</uri>
              <name>Gazebo/Grey</name>
            </script>
          </material>
        </visual>
        <self_collide>0</self_collide>
        <enable_wind>0</enable_wind>
        <kinematic>0</kinematic>
      </link>
    </model>
    <gravity>0 0 -9.8</gravity>
    <magnetic_field>6e-06 2.3e-05 -4.2e-05</magnetic_field>
    <atmosphere type='adiabatic'/>
    <physics type='ode'>
      <max_step_size>0.001</max_step_size>
      <real_time_factor>1</real_time_factor>
      <real_time_update_rate>1000</real_time_update_rate>
    </physics>
    <scene>
      <ambient>0.4 0.4 0.4 1</ambient>
      <background>0.7 0.7 0.7 1</background>
      <shadows>1</shadows>
    </scene>
    <audio>
      <device>default</device>
    </audio>
    <wind/>
    <spherical_coordinates>
      <surface_model>EARTH_WGS84</surface_model>
      <latitude_deg>0</latitude_deg>
      <longitude_deg>0</longitude_deg>
      <elevation>0</elevation>
      <heading_deg>0</heading_deg>
    </spherical_coordinates>
    <state world_name='default'>
      <sim_time>1099 571000000</sim_time>
      <real_time>118 432730802</real_time>
      <wall_time>1713862526 333815229</wall_time>
      <iterations>115652</iterations>
      <model name='ground_plane'>
        <pose>0 0 0 0 -0 0</pose>
        <scale>1 1 1</scale>
        <link name='link'>
          <pose>0 0 0 0 -0 0</pose>
          <velocity>0 0 0 0 -0 0</velocity>
          <acceleration>0 0 0 0 -0 0</acceleration>
          <wrench>0 0 0 0 -0 0</wrench>
        </link>
      </model>
      <model name='model'>
        <pose>0.008468 0.817097 0.088981 0 -0 0</pose>
        <scale>1 1 1</scale>
        <link name='link_0'>
          <pose>0.089947 -0.065025 0.088981 0 -0 0</pose>
          <velocity>0 0 0 0 -0 0</velocity>
          <acceleration>0 0 0 0 -0 0</acceleration>
          <wrench>0 0 0 0 -0 0</wrench>
        </link>
        <link name='link_0_clone'>
          <pose>-0.074462 0.280975 0.088981 0 -0 0</pose>
          <velocity>0 0 0 0 -0 0</velocity>
          <acceleration>0 0 0 0 -0 0</acceleration>
          <wrench>0 0 0 0 -0 0</wrench>
        </link>
        <link name='link_0_clone_0'>
          <pose>0.087021 0.636544 0.088981 0 -0 0</pose>
          <velocity>0 0 0 0 -0 0</velocity>
          <acceleration>0 0 0 0 -0 0</acceleration>
          <wrench>0 0 0 0 -0 0</wrench>
        </link>
        <link name='link_0_clone_1'>
          <pose>-0.067628 0.99246 0.088981 0 -0 0</pose>
          <velocity>0 0 0 0 -0 0</velocity>
          <acceleration>0 0 0 0 -0 0</acceleration>
          <wrench>0 0 0 0 -0 0</wrench>
        </link>
        <link name='link_0_clone_1_clone'>
          <pose>0.090628 1.34814 0.088981 0 -0 0</pose>
          <velocity>0 0 0 0 -0 0</velocity>
          <acceleration>0 0 0 0 -0 0</acceleration>
          <wrench>0 0 0 0 -0 0</wrench>
        </link>
        <link name='link_0_clone_1_clone_0'>
          <pose>-0.0648 1.7028 0.088981 0 -0 0</pose>
          <velocity>0 0 0 0 -0 0</velocity>
          <acceleration>0 0 0 0 -0 0</acceleration>
          <wrench>0 0 0 0 -0 0</wrench>
        </link>
        <link name='link_0_clone_1_clone_1'>
          <pose>0.111134 2.05089 0.088981 0 -0 0</pose>
          <velocity>0 0 0 0 -0 0</velocity>
          <acceleration>0 0 0 0 -0 0</acceleration>
          <wrench>0 0 0 0 -0 0</wrench>
        </link>
        <link name='link_0_clone_2'>
          <pose>-0.104096 -0.410003 0.088981 0 -0 0</pose>
          <velocity>0 0 0 0 -0 0</velocity>
          <acceleration>0 0 0 0 -0 0</acceleration>
          <wrench>0 0 0 0 -0 0</wrench>
        </link>
      </model>
      <model name='my_bot'>
        <pose>-0.000781 -0.024236 1e-06 -3e-06 -9e-06 -0.011136</pose>
        <scale>1 1 1</scale>
        <link name='base_link'>
          <pose>-0.000781 -0.024236 1e-06 -3e-06 -9e-06 -0.011136</pose>
          <velocity>0.000977 0.000201 -0.001097 0.001744 0.030183 0.006978</velocity>
          <acceleration>2.41483 0.063777 -2.45683 -2.65597 -0.862322 -1.00107</acceleration>
          <wrench>2.41483 0.063777 -2.45683 0 -0 0</wrench>
        </link>
        <link name='link_10'>
          <pose>0.01491 1.55069 -0 1e-06 -1e-06 0.00737</pose>
          <velocity>-0 -0 0.008893 0.01741 0.038509 1e-06</velocity>
          <acceleration>0.335946 -1.07185 21.2016 3.13829 1.3362 -3.08549</acceleration>
          <wrench>0.335946 -1.07185 21.2016 0 -0 0</wrench>
        </link>
        <link name='link_2'>
          <pose>0.001167 0.150753 0 -1e-06 -9e-06 -0.008635</pose>
          <velocity>-0.000155 0.000173 -0.000928 0.000967 0.02909 0.015834</velocity>
          <acceleration>0.803889 0.123329 -2.16176 2.46706 -0.19711 -2.99084</acceleration>
          <wrench>0.803889 0.123329 -2.16176 0 -0 0</wrench>
        </link>
        <link name='link_3'>
          <pose>0.002678 0.325747 1e-06 0 -2e-06 -0.009003</pose>
          <velocity>-0.003013 9e-05 -0.000796 0.001343 0.02615 -0.01668</velocity>
          <acceleration>0.040262 0.139081 -1.72879 -0.155962 0.98645 0.523495</acceleration>
          <wrench>0.040262 0.139081 -1.72879 0 -0 0</wrench>
        </link>
        <link name='link_4'>
          <pose>0.004253 0.500741 -0 8e-06 -7e-06 -0.009464</pose>
          <velocity>-5e-06 0.000101 -0.000698 0.005744 0.021605 0.003562</velocity>
          <acceleration>1.53164 -0.289522 -1.03958 -2.95079 -0.553417 -0.570518</acceleration>
          <wrench>1.53164 -0.289522 -1.03958 0 -0 0</wrench>
        </link>
        <link name='link_5'>
          <pose>0.005907 0.675733 0 -3e-06 -1e-06 -0.007374</pose>
          <velocity>-0 -0 0.000852 0.003115 0.002742 3e-06</velocity>
          <acceleration>2.11086 0.429019 2.06613 -2.99633 -0.9996 0.700513</acceleration>
          <wrench>2.11086 0.429019 2.06613 0 -0 0</wrench>
        </link>
        <link name='link_6'>
          <pose>0.007196 0.850728 0 0 2e-06 -0.008498</pose>
          <velocity>0 -0 0.00113 -0.001996 0.02223 0</velocity>
          <acceleration>2.31517 0.560031 2.31117 2.43955 1.56459 0.77772</acceleration>
          <wrench>2.31517 0.560031 2.31117 0 -0 0</wrench>
        </link>
        <link name='link_7'>
          <pose>0.008683 1.02572 0 3e-06 -9e-06 -0.009778</pose>
          <velocity>-1e-05 -1e-05 0.000953 0.003789 0.026176 -0.000185</velocity>
          <acceleration>2.20599 -0.390773 2.5998 0.508565 -1.17761 0.023827</acceleration>
          <wrench>2.20599 -0.390773 2.5998 0 -0 0</wrench>
        </link>
        <link name='link_8'>
          <pose>0.010394 1.20071 -0 5e-06 -0 -0.013156</pose>
          <velocity>0 -0 0.001868 0.021095 0.045282 -5e-06</velocity>
          <acceleration>2.07744 -1.09329 7.57855 0.266993 0.068366 1.24565</acceleration>
          <wrench>2.07744 -1.09329 7.57855 0 -0 0</wrench>
        </link>
        <link name='link_9'>
          <pose>0.012697 1.3757 0 -0 -1e-06 -0.012645</pose>
          <velocity>-0 -0 0.005169 0.024276 0.048741 0</velocity>
          <acceleration>1.62609 -1.30344 14.3233 -0.563926 -0.88518 -1.79525</acceleration>
          <wrench>1.62609 -1.30344 14.3233 0 -0 0</wrench>
        </link>
      </model>
      <light name='sun'>
        <pose>0 0 10 0 -0 0</pose>
      </light>
    </state>
    <gui fullscreen='0'>
      <camera name='user_camera'>
        <pose>0.03407 0.58122 3.67033 1e-06 1.5498 1.57483</pose>
        <view_controller>orbit</view_controller>
        <projection_type>perspective</projection_type>
      </camera>
    </gui>
    <model name='my_bot'>
      <link name='base_link'>
        <inertial>
          <pose>0 0.07 0.03 0 -0 0</pose>
          <mass>1</mass>
          <inertia>
            <ixx>0.00193333</ixx>
            <ixy>0</ixy>
            <ixz>0</ixz>
            <iyy>0.0006</iyy>
            <iyz>0</iyz>
            <izz>0.00193333</izz>
          </inertia>
        </inertial>
        <collision name='base_link_fixed_joint_lump__link_1_collision'>
          <pose>0 0.07 0.03 0 -0 0</pose>
          <geometry>
            <box>
              <size>0.06 0.14 0.06</size>
            </box>
          </geometry>
          <surface>
            <contact>
              <ode/>
            </contact>
            <friction>
              <ode/>
              <torsional>
                <ode/>
              </torsional>
            </friction>
            <bounce/>
          </surface>
          <max_contacts>10</max_contacts>
        </collision>
        <visual name='base_link_fixed_joint_lump__link_1_visual'>
          <pose>0 0.07 0.03 0 -0 0</pose>
          <geometry>
            <box>
              <size>0.06 0.14 0.06</size>
            </box>
          </geometry>
          <material>
            <script>
              <name>Gazebo/Green</name>
              <uri>file://media/materials/scripts/gazebo.material</uri>
            </script>
          </material>
        </visual>
        <visual name='base_link_fixed_joint_lump__camera_link_visual_1'>
          <pose>0 0 0.03 0 0 -1.5708</pose>
          <geometry>
            <box>
              <size>0.01 0.01 0.01</size>
            </box>
          </geometry>
          <material>
            <script>
              <name>Gazebo/Red</name>
              <uri>file://media/materials/scripts/gazebo.material</uri>
            </script>
          </material>
        </visual>
        <sensor name='camera' type='camera'>
          <visualize>1</visualize>
          <update_rate>10</update_rate>
          <camera>
            <horizontal_fov>1.089</horizontal_fov>
            <image>
              <format>R8G8B8</format>
              <width>640</width>
              <height>480</height>
            </image>
            <clip>
              <near>0.05</near>
              <far>8</far>
            </clip>
          </camera>
          <plugin name='camera_controller' filename='libgazebo_ros_camera.so'>
            <frame_name>camera_link_optical</frame_name>
          </plugin>
          <pose>0 0 0.03 0 0 -1.5708</pose>
        </sensor>
        <self_collide>0</self_collide>
        <enable_wind>0</enable_wind>
        <kinematic>0</kinematic>
      </link>
      <joint name='link_1_2_joint' type='revolute'>
        <pose relative_to='base_link'>0 0.175 0 0 -0 0</pose>
        <parent>base_link</parent>
        <child>link_2</child>
        <axis>
          <xyz>0 0 1</xyz>
          <limit>
            <lower>-0.785398</lower>
            <upper>0.785398</upper>
            <effort>1000</effort>
            <velocity>50</velocity>
          </limit>
          <dynamics>
            <spring_reference>0</spring_reference>
            <spring_stiffness>0</spring_stiffness>
          </dynamics>
        </axis>
      </joint>
      <link name='link_2'>
        <pose relative_to='link_1_2_joint'>0 0 0 0 -0 0</pose>
        <inertial>
          <pose>0 0.07 0.03 0 -0 0</pose>
          <mass>1</mass>
          <inertia>
            <ixx>0.00193333</ixx>
            <ixy>0</ixy>
            <ixz>0</ixz>
            <iyy>0.0006</iyy>
            <iyz>0</iyz>
            <izz>0.00193333</izz>
          </inertia>
        </inertial>
        <collision name='link_2_collision'>
          <pose>0 0.07 0.03 0 -0 0</pose>
          <geometry>
            <box>
              <size>0.06 0.14 0.06</size>
            </box>
          </geometry>
          <surface>
            <contact>
              <ode/>
            </contact>
            <friction>
              <ode/>
              <torsional>
                <ode/>
              </torsional>
            </friction>
            <bounce/>
          </surface>
          <max_contacts>10</max_contacts>
        </collision>
        <visual name='link_2_visual'>
          <pose>0 0.07 0.03 0 -0 0</pose>
          <geometry>
            <box>
              <size>0.06 0.14 0.06</size>
            </box>
          </geometry>
          <material>
            <script>
              <name>Gazebo/Blue</name>
              <uri>file://media/materials/scripts/gazebo.material</uri>
            </script>
          </material>
        </visual>
        <self_collide>0</self_collide>
        <enable_wind>0</enable_wind>
        <kinematic>0</kinematic>
      </link>
      <joint name='link_2_3_joint' type='revolute'>
        <pose relative_to='link_2'>0 0.175 0 0 -0 0</pose>
        <parent>link_2</parent>
        <child>link_3</child>
        <axis>
          <xyz>0 0 1</xyz>
          <limit>
            <lower>-0.785398</lower>
            <upper>0.785398</upper>
            <effort>1000</effort>
            <velocity>50</velocity>
          </limit>
          <dynamics>
            <spring_reference>0</spring_reference>
            <spring_stiffness>0</spring_stiffness>
          </dynamics>
        </axis>
      </joint>
      <link name='link_3'>
        <pose relative_to='link_2_3_joint'>0 0 0 0 -0 0</pose>
        <inertial>
          <pose>0 0.07 0.03 0 -0 0</pose>
          <mass>1</mass>
          <inertia>
            <ixx>0.00193333</ixx>
            <ixy>0</ixy>
            <ixz>0</ixz>
            <iyy>0.0006</iyy>
            <iyz>0</iyz>
            <izz>0.00193333</izz>
          </inertia>
        </inertial>
        <collision name='link_3_collision'>
          <pose>0 0.07 0.03 0 -0 0</pose>
          <geometry>
            <box>
              <size>0.06 0.14 0.06</size>
            </box>
          </geometry>
          <surface>
            <contact>
              <ode/>
            </contact>
            <friction>
              <ode/>
              <torsional>
                <ode/>
              </torsional>
            </friction>
            <bounce/>
          </surface>
          <max_contacts>10</max_contacts>
        </collision>
        <visual name='link_3_visual'>
          <pose>0 0.07 0.03 0 -0 0</pose>
          <geometry>
            <box>
              <size>0.06 0.14 0.06</size>
            </box>
          </geometry>
          <material>
            <script>
              <name>Gazebo/Orange</name>
              <uri>file://media/materials/scripts/gazebo.material</uri>
            </script>
          </material>
        </visual>
        <self_collide>0</self_collide>
        <enable_wind>0</enable_wind>
        <kinematic>0</kinematic>
      </link>
      <joint name='link_3_4_joint' type='revolute'>
        <pose relative_to='link_3'>0 0.175 0 0 -0 0</pose>
        <parent>link_3</parent>
        <child>link_4</child>
        <axis>
          <xyz>0 0 1</xyz>
          <limit>
            <lower>-0.785398</lower>
            <upper>0.785398</upper>
            <effort>1000</effort>
            <velocity>50</velocity>
          </limit>
          <dynamics>
            <spring_reference>0</spring_reference>
            <spring_stiffness>0</spring_stiffness>
          </dynamics>
        </axis>
      </joint>
      <link name='link_4'>
        <pose relative_to='link_3_4_joint'>0 0 0 0 -0 0</pose>
        <inertial>
          <pose>0 0.07 0.03 0 -0 0</pose>
          <mass>1</mass>
          <inertia>
            <ixx>0.00193333</ixx>
            <ixy>0</ixy>
            <ixz>0</ixz>
            <iyy>0.0006</iyy>
            <iyz>0</iyz>
            <izz>0.00193333</izz>
          </inertia>
        </inertial>
        <collision name='link_4_collision'>
          <pose>0 0.07 0.03 0 -0 0</pose>
          <geometry>
            <box>
              <size>0.06 0.14 0.06</size>
            </box>
          </geometry>
          <surface>
            <contact>
              <ode/>
            </contact>
            <friction>
              <ode/>
              <torsional>
                <ode/>
              </torsional>
            </friction>
            <bounce/>
          </surface>
          <max_contacts>10</max_contacts>
        </collision>
        <visual name='link_4_visual'>
          <pose>0 0.07 0.03 0 -0 0</pose>
          <geometry>
            <box>
              <size>0.06 0.14 0.06</size>
            </box>
          </geometry>
          <material>
            <script>
              <name>Gazebo/Blue</name>
              <uri>file://media/materials/scripts/gazebo.material</uri>
            </script>
          </material>
        </visual>
        <self_collide>0</self_collide>
        <enable_wind>0</enable_wind>
        <kinematic>0</kinematic>
      </link>
      <joint name='link_4_5_joint' type='revolute'>
        <pose relative_to='link_4'>0 0.175 0 0 -0 0</pose>
        <parent>link_4</parent>
        <child>link_5</child>
        <axis>
          <xyz>0 0 1</xyz>
          <limit>
            <lower>-0.785398</lower>
            <upper>0.785398</upper>
            <effort>1000</effort>
            <velocity>50</velocity>
          </limit>
          <dynamics>
            <spring_reference>0</spring_reference>
            <spring_stiffness>0</spring_stiffness>
          </dynamics>
        </axis>
      </joint>
      <link name='link_5'>
        <pose relative_to='link_4_5_joint'>0 0 0 0 -0 0</pose>
        <inertial>
          <pose>0 0.07 0.03 0 -0 0</pose>
          <mass>1</mass>
          <inertia>
            <ixx>0.00193333</ixx>
            <ixy>0</ixy>
            <ixz>0</ixz>
            <iyy>0.0006</iyy>
            <iyz>0</iyz>
            <izz>0.00193333</izz>
          </inertia>
        </inertial>
        <collision name='link_5_collision'>
          <pose>0 0.07 0.03 0 -0 0</pose>
          <geometry>
            <box>
              <size>0.06 0.14 0.06</size>
            </box>
          </geometry>
          <surface>
            <contact>
              <ode/>
            </contact>
            <friction>
              <ode/>
              <torsional>
                <ode/>
              </torsional>
            </friction>
            <bounce/>
          </surface>
          <max_contacts>10</max_contacts>
        </collision>
        <visual name='link_5_visual'>
          <pose>0 0.07 0.03 0 -0 0</pose>
          <geometry>
            <box>
              <size>0.06 0.14 0.06</size>
            </box>
          </geometry>
          <material>
            <script>
              <name>Gazebo/Green</name>
              <uri>file://media/materials/scripts/gazebo.material</uri>
            </script>
          </material>
        </visual>
        <self_collide>0</self_collide>
        <enable_wind>0</enable_wind>
        <kinematic>0</kinematic>
      </link>
      <joint name='link_5_6_joint' type='revolute'>
        <pose relative_to='link_5'>0 0.175 0 0 -0 0</pose>
        <parent>link_5</parent>
        <child>link_6</child>
        <axis>
          <xyz>0 0 1</xyz>
          <limit>
            <lower>-0.785398</lower>
            <upper>0.785398</upper>
            <effort>1000</effort>
            <velocity>50</velocity>
          </limit>
          <dynamics>
            <spring_reference>0</spring_reference>
            <spring_stiffness>0</spring_stiffness>
          </dynamics>
        </axis>
      </joint>
      <link name='link_6'>
        <pose relative_to='link_5_6_joint'>0 0 0 0 -0 0</pose>
        <inertial>
          <pose>0 0.07 0.03 0 -0 0</pose>
          <mass>1</mass>
          <inertia>
            <ixx>0.00193333</ixx>
            <ixy>0</ixy>
            <ixz>0</ixz>
            <iyy>0.0006</iyy>
            <iyz>0</iyz>
            <izz>0.00193333</izz>
          </inertia>
        </inertial>
        <collision name='link_6_collision'>
          <pose>0 0.07 0.03 0 -0 0</pose>
          <geometry>
            <box>
              <size>0.06 0.14 0.06</size>
            </box>
          </geometry>
          <surface>
            <contact>
              <ode/>
            </contact>
            <friction>
              <ode/>
              <torsional>
                <ode/>
              </torsional>
            </friction>
            <bounce/>
          </surface>
          <max_contacts>10</max_contacts>
        </collision>
        <visual name='link_6_visual'>
          <pose>0 0.07 0.03 0 -0 0</pose>
          <geometry>
            <box>
              <size>0.06 0.14 0.06</size>
            </box>
          </geometry>
          <material>
            <script>
              <name>Gazebo/Blue</name>
              <uri>file://media/materials/scripts/gazebo.material</uri>
            </script>
          </material>
        </visual>
        <self_collide>0</self_collide>
        <enable_wind>0</enable_wind>
        <kinematic>0</kinematic>
      </link>
      <joint name='link_6_7_joint' type='revolute'>
        <pose relative_to='link_6'>0 0.175 0 0 -0 0</pose>
        <parent>link_6</parent>
        <child>link_7</child>
        <axis>
          <xyz>0 0 1</xyz>
          <limit>
            <lower>-0.785398</lower>
            <upper>0.785398</upper>
            <effort>1000</effort>
            <velocity>50</velocity>
          </limit>
          <dynamics>
            <spring_reference>0</spring_reference>
            <spring_stiffness>0</spring_stiffness>
          </dynamics>
        </axis>
      </joint>
      <link name='link_7'>
        <pose relative_to='link_6_7_joint'>0 0 0 0 -0 0</pose>
        <inertial>
          <pose>0 0.07 0.03 0 -0 0</pose>
          <mass>1</mass>
          <inertia>
            <ixx>0.00193333</ixx>
            <ixy>0</ixy>
            <ixz>0</ixz>
            <iyy>0.0006</iyy>
            <iyz>0</iyz>
            <izz>0.00193333</izz>
          </inertia>
        </inertial>
        <collision name='link_7_collision'>
          <pose>0 0.07 0.03 0 -0 0</pose>
          <geometry>
            <box>
              <size>0.06 0.14 0.06</size>
            </box>
          </geometry>
          <surface>
            <contact>
              <ode/>
            </contact>
            <friction>
              <ode/>
              <torsional>
                <ode/>
              </torsional>
            </friction>
            <bounce/>
          </surface>
          <max_contacts>10</max_contacts>
        </collision>
        <visual name='link_7_visual'>
          <pose>0 0.07 0.03 0 -0 0</pose>
          <geometry>
            <box>
              <size>0.06 0.14 0.06</size>
            </box>
          </geometry>
          <material>
            <script>
              <name>Gazebo/Orange</name>
              <uri>file://media/materials/scripts/gazebo.material</uri>
            </script>
          </material>
        </visual>
        <self_collide>0</self_collide>
        <enable_wind>0</enable_wind>
        <kinematic>0</kinematic>
      </link>
      <joint name='link_7_8_joint' type='revolute'>
        <pose relative_to='link_7'>0 0.175 0 0 -0 0</pose>
        <parent>link_7</parent>
        <child>link_8</child>
        <axis>
          <xyz>0 0 1</xyz>
          <limit>
            <lower>-0.785398</lower>
            <upper>0.785398</upper>
            <effort>1000</effort>
            <velocity>50</velocity>
          </limit>
          <dynamics>
            <spring_reference>0</spring_reference>
            <spring_stiffness>0</spring_stiffness>
          </dynamics>
        </axis>
      </joint>
      <link name='link_8'>
        <pose relative_to='link_7_8_joint'>0 0 0 0 -0 0</pose>
        <inertial>
          <pose>0 0.07 0.03 0 -0 0</pose>
          <mass>1</mass>
          <inertia>
            <ixx>0.00193333</ixx>
            <ixy>0</ixy>
            <ixz>0</ixz>
            <iyy>0.0006</iyy>
            <iyz>0</iyz>
            <izz>0.00193333</izz>
          </inertia>
        </inertial>
        <collision name='link_8_collision'>
          <pose>0 0.07 0.03 0 -0 0</pose>
          <geometry>
            <box>
              <size>0.06 0.14 0.06</size>
            </box>
          </geometry>
          <surface>
            <contact>
              <ode/>
            </contact>
            <friction>
              <ode/>
              <torsional>
                <ode/>
              </torsional>
            </friction>
            <bounce/>
          </surface>
          <max_contacts>10</max_contacts>
        </collision>
        <visual name='link_8_visual'>
          <pose>0 0.07 0.03 0 -0 0</pose>
          <geometry>
            <box>
              <size>0.06 0.14 0.06</size>
            </box>
          </geometry>
          <material>
            <script>
              <name>Gazebo/Green</name>
              <uri>file://media/materials/scripts/gazebo.material</uri>
            </script>
          </material>
        </visual>
        <self_collide>0</self_collide>
        <enable_wind>0</enable_wind>
        <kinematic>0</kinematic>
      </link>
      <joint name='link_8_9_joint' type='revolute'>
        <pose relative_to='link_8'>0 0.175 0 0 -0 0</pose>
        <parent>link_8</parent>
        <child>link_9</child>
        <axis>
          <xyz>0 0 1</xyz>
          <limit>
            <lower>-0.785398</lower>
            <upper>0.785398</upper>
            <effort>1000</effort>
            <velocity>50</velocity>
          </limit>
          <dynamics>
            <spring_reference>0</spring_reference>
            <spring_stiffness>0</spring_stiffness>
          </dynamics>
        </axis>
      </joint>
      <link name='link_9'>
        <pose relative_to='link_8_9_joint'>0 0 0 0 -0 0</pose>
        <inertial>
          <pose>0 0.07 0.03 0 -0 0</pose>
          <mass>1</mass>
          <inertia>
            <ixx>0.00193333</ixx>
            <ixy>0</ixy>
            <ixz>0</ixz>
            <iyy>0.0006</iyy>
            <iyz>0</iyz>
            <izz>0.00193333</izz>
          </inertia>
        </inertial>
        <collision name='link_9_collision'>
          <pose>0 0.07 0.03 0 -0 0</pose>
          <geometry>
            <box>
              <size>0.06 0.14 0.06</size>
            </box>
          </geometry>
          <surface>
            <contact>
              <ode/>
            </contact>
            <friction>
              <ode/>
              <torsional>
                <ode/>
              </torsional>
            </friction>
            <bounce/>
          </surface>
          <max_contacts>10</max_contacts>
        </collision>
        <visual name='link_9_visual'>
          <pose>0 0.07 0.03 0 -0 0</pose>
          <geometry>
            <box>
              <size>0.06 0.14 0.06</size>
            </box>
          </geometry>
          <material>
            <script>
              <name>Gazebo/Blue</name>
              <uri>file://media/materials/scripts/gazebo.material</uri>
            </script>
          </material>
        </visual>
        <self_collide>0</self_collide>
        <enable_wind>0</enable_wind>
        <kinematic>0</kinematic>
      </link>
      <joint name='link_9_10_joint' type='revolute'>
        <pose relative_to='link_9'>0 0.175 0 0 -0 0</pose>
        <parent>link_9</parent>
        <child>link_10</child>
        <axis>
          <xyz>0 0 1</xyz>
          <limit>
            <lower>-0.785398</lower>
            <upper>0.785398</upper>
            <effort>1000</effort>
            <velocity>50</velocity>
          </limit>
          <dynamics>
            <spring_reference>0</spring_reference>
            <spring_stiffness>0</spring_stiffness>
          </dynamics>
        </axis>
      </joint>
      <link name='link_10'>
        <pose relative_to='link_9_10_joint'>0 0 0 0 -0 0</pose>
        <inertial>
          <pose>0 0.07 0.03 0 -0 0</pose>
          <mass>1</mass>
          <inertia>
            <ixx>0.00193333</ixx>
            <ixy>0</ixy>
            <ixz>0</ixz>
            <iyy>0.0006</iyy>
            <iyz>0</iyz>
            <izz>0.00193333</izz>
          </inertia>
        </inertial>
        <collision name='link_10_collision'>
          <pose>0 0.07 0.03 0 -0 0</pose>
          <geometry>
            <box>
              <size>0.06 0.14 0.06</size>
            </box>
          </geometry>
          <surface>
            <contact>
              <ode/>
            </contact>
            <friction>
              <ode/>
              <torsional>
                <ode/>
              </torsional>
            </friction>
            <bounce/>
          </surface>
          <max_contacts>10</max_contacts>
        </collision>
        <visual name='link_10_visual'>
          <pose>0 0.07 0.03 0 -0 0</pose>
          <geometry>
            <box>
              <size>0.06 0.14 0.06</size>
            </box>
          </geometry>
          <material>
            <script>
              <name>Gazebo/Orange</name>
              <uri>file://media/materials/scripts/gazebo.material</uri>
            </script>
          </material>
        </visual>
        <self_collide>0</self_collide>
        <enable_wind>0</enable_wind>
        <kinematic>0</kinematic>
      </link>
      <static>0</static>
      <plugin name='gazebo_ros_planar_move' filename='libgazebo_ros_planar_move.so'>
        <update_rate>100</update_rate>
        <publish_rate>10</publish_rate>
        <publish_odom>1</publish_odom>
        <publish_odom_tf>1</publish_odom_tf>
        <odometry_frame>odom</odometry_frame>
        <robot_base_frame>base_link</robot_base_frame>
      </plugin>
      <plugin name='gazebo_ros2_control' filename='libgazebo_ros2_control.so'>
        <parameters>/home/mohit/GITHUBRepos/snake-robot-sim/install/snake_bot/share/snake_bot/config/controllers.yaml</parameters>
      </plugin>
      <plugin name='ft_sensor' filename='libgazebo_ros_ft_sensor.so'>
        <updateRate>100.0</updateRate>
        <remapping>wrench:=joint_1</remapping>
        <joint_name>link_1_2_joint</joint_name>
        <gaussian_noise>0.01</gaussian_noise>
        <update_rate>1</update_rate>
      </plugin>
      <pose>0 0 0 0 -0 0</pose>
    </model>
    <model name='model'>
      <link name='link_0'>
        <inertial>
          <mass>1e+10</mass>
          <inertia>
            <ixx>3.11188e+07</ixx>
            <ixy>0</ixy>
            <ixz>0</ixz>
            <iyy>3.11188e+07</iyy>
            <iyz>0</iyz>
            <izz>1.00639e+07</izz>
          </inertia>
          <pose>0 0 0 0 -0 0</pose>
        </inertial>
        <pose>0.081479 -0.882122 0 0 -0 0</pose>
        <gravity>1</gravity>
        <self_collide>0</self_collide>
        <kinematic>0</kinematic>
        <enable_wind>0</enable_wind>
        <visual name='visual'>
          <pose>0 0 0 0 -0 0</pose>
          <geometry>
            <cylinder>
              <radius>0.0448636</radius>
              <length>0.17693</length>
            </cylinder>
          </geometry>
          <material>
            <lighting>1</lighting>
            <script>
              <uri>file://media/materials/scripts/gazebo.material</uri>
              <name>Gazebo/Red</name>
            </script>
            <shader type='pixel'>
              <normal_map>__default__</normal_map>
            </shader>
            <ambient>1 0 0 1</ambient>
            <diffuse>1 0 0 1</diffuse>
            <specular>0.1 0.1 0.1 1</specular>
            <emissive>0 0 0 1</emissive>
          </material>
          <transparency>0</transparency>
          <cast_shadows>1</cast_shadows>
        </visual>
        <collision name='collision'>
          <laser_retro>0</laser_retro>
          <max_contacts>10</max_contacts>
          <pose>0 0 0 0 -0 0</pose>
          <geometry>
            <cylinder>
              <radius>0.044864</radius>
              <length>0.17693</length>
            </cylinder>
          </geometry>
          <surface>
            <friction>
              <ode>
                <mu>1</mu>
                <mu2>1</mu2>
                <fdir1>0 0 0</fdir1>
                <slip1>0</slip1>
                <slip2>0</slip2>
              </ode>
              <torsional>
                <coefficient>1</coefficient>
                <patch_radius>0</patch_radius>
                <surface_radius>0</surface_radius>
                <use_patch_radius>1</use_patch_radius>
                <ode>
                  <slip>0</slip>
                </ode>
              </torsional>
            </friction>
            <bounce>
              <restitution_coefficient>0</restitution_coefficient>
              <threshold>1e+06</threshold>
            </bounce>
            <contact>
              <collide_without_contact>0</collide_without_contact>
              <collide_without_contact_bitmask>1</collide_without_contact_bitmask>
              <collide_bitmask>1</collide_bitmask>
              <ode>
                <soft_cfm>0</soft_cfm>
                <soft_erp>0.2</soft_erp>
                <kp>1e+13</kp>
                <kd>1</kd>
                <max_vel>0.01</max_vel>
                <min_depth>0</min_depth>
              </ode>
              <bullet>
                <split_impulse>1</split_impulse>
                <split_impulse_penetration_threshold>-0.01</split_impulse_penetration_threshold>
                <soft_cfm>0</soft_cfm>
                <soft_erp>0.2</soft_erp>
                <kp>1e+13</kp>
                <kd>1</kd>
              </bullet>
            </contact>
          </surface>
        </collision>
      </link>
      <link name='link_0_clone'>
        <inertial>
          <mass>1e+10</mass>
          <inertia>
            <ixx>3.11188e+07</ixx>
            <ixy>0</ixy>
            <ixz>0</ixz>
            <iyy>3.11188e+07</iyy>
            <iyz>0</iyz>
            <izz>1.00639e+07</izz>
          </inertia>
          <pose>0 0 0 0 -0 0</pose>
        </inertial>
        <pose>-0.08293 -0.536122 0 0 -0 0</pose>
        <gravity>1</gravity>
        <self_collide>0</self_collide>
        <kinematic>0</kinematic>
        <enable_wind>0</enable_wind>
        <visual name='visual'>
          <pose>0 0 0 0 -0 0</pose>
          <geometry>
            <cylinder>
              <radius>0.0448636</radius>
              <length>0.17693</length>
            </cylinder>
          </geometry>
          <material>
            <lighting>1</lighting>
            <script>
              <uri>file://media/materials/scripts/gazebo.material</uri>
              <name>Gazebo/Red</name>
            </script>
            <shader type='pixel'>
              <normal_map>__default__</normal_map>
            </shader>
            <ambient>1 0 0 1</ambient>
            <diffuse>1 0 0 1</diffuse>
            <specular>0.1 0.1 0.1 1</specular>
            <emissive>0 0 0 1</emissive>
          </material>
          <transparency>0</transparency>
          <cast_shadows>1</cast_shadows>
        </visual>
        <collision name='collision'>
          <laser_retro>0</laser_retro>
          <max_contacts>10</max_contacts>
          <pose>0 0 0 0 -0 0</pose>
          <geometry>
            <cylinder>
              <radius>0.044864</radius>
              <length>0.17693</length>
            </cylinder>
          </geometry>
          <surface>
            <friction>
              <ode>
                <mu>1</mu>
                <mu2>1</mu2>
                <fdir1>0 0 0</fdir1>
                <slip1>0</slip1>
                <slip2>0</slip2>
              </ode>
              <torsional>
                <coefficient>1</coefficient>
                <patch_radius>0</patch_radius>
                <surface_radius>0</surface_radius>
                <use_patch_radius>1</use_patch_radius>
                <ode>
                  <slip>0</slip>
                </ode>
              </torsional>
            </friction>
            <bounce>
              <restitution_coefficient>0</restitution_coefficient>
              <threshold>1e+06</threshold>
            </bounce>
            <contact>
              <collide_without_contact>0</collide_without_contact>
              <collide_without_contact_bitmask>1</collide_without_contact_bitmask>
              <collide_bitmask>1</collide_bitmask>
              <ode>
                <soft_cfm>0</soft_cfm>
                <soft_erp>0.2</soft_erp>
                <kp>1e+13</kp>
                <kd>1</kd>
                <max_vel>0.01</max_vel>
                <min_depth>0</min_depth>
              </ode>
              <bullet>
                <split_impulse>1</split_impulse>
                <split_impulse_penetration_threshold>-0.01</split_impulse_penetration_threshold>
                <soft_cfm>0</soft_cfm>
                <soft_erp>0.2</soft_erp>
                <kp>1e+13</kp>
                <kd>1</kd>
              </bullet>
            </contact>
          </surface>
        </collision>
      </link>
      <link name='link_0_clone_0'>
        <inertial>
          <mass>1e+10</mass>
          <inertia>
            <ixx>3.11188e+07</ixx>
            <ixy>0</ixy>
            <ixz>0</ixz>
            <iyy>3.11188e+07</iyy>
            <iyz>0</iyz>
            <izz>1.00639e+07</izz>
          </inertia>
          <pose>0 0 0 0 -0 0</pose>
        </inertial>
        <pose>0.078553 -0.180553 0 0 -0 0</pose>
        <gravity>1</gravity>
        <self_collide>0</self_collide>
        <kinematic>0</kinematic>
        <enable_wind>0</enable_wind>
        <visual name='visual'>
          <pose>0 0 0 0 -0 0</pose>
          <geometry>
            <cylinder>
              <radius>0.0448636</radius>
              <length>0.17693</length>
            </cylinder>
          </geometry>
          <material>
            <lighting>1</lighting>
            <script>
              <uri>file://media/materials/scripts/gazebo.material</uri>
              <name>Gazebo/Red</name>
            </script>
            <shader type='pixel'>
              <normal_map>__default__</normal_map>
            </shader>
            <ambient>1 0 0 1</ambient>
            <diffuse>1 0 0 1</diffuse>
            <specular>0.1 0.1 0.1 1</specular>
            <emissive>0 0 0 1</emissive>
          </material>
          <transparency>0</transparency>
          <cast_shadows>1</cast_shadows>
        </visual>
        <collision name='collision'>
          <laser_retro>0</laser_retro>
          <max_contacts>10</max_contacts>
          <pose>0 0 0 0 -0 0</pose>
          <geometry>
            <cylinder>
              <radius>0.044864</radius>
              <length>0.17693</length>
            </cylinder>
          </geometry>
          <surface>
            <friction>
              <ode>
                <mu>1</mu>
                <mu2>1</mu2>
                <fdir1>0 0 0</fdir1>
                <slip1>0</slip1>
                <slip2>0</slip2>
              </ode>
              <torsional>
                <coefficient>1</coefficient>
                <patch_radius>0</patch_radius>
                <surface_radius>0</surface_radius>
                <use_patch_radius>1</use_patch_radius>
                <ode>
                  <slip>0</slip>
                </ode>
              </torsional>
            </friction>
            <bounce>
              <restitution_coefficient>0</restitution_coefficient>
              <threshold>1e+06</threshold>
            </bounce>
            <contact>
              <collide_without_contact>0</collide_without_contact>
              <collide_without_contact_bitmask>1</collide_without_contact_bitmask>
              <collide_bitmask>1</collide_bitmask>
              <ode>
                <soft_cfm>0</soft_cfm>
                <soft_erp>0.2</soft_erp>
                <kp>1e+13</kp>
                <kd>1</kd>
                <max_vel>0.01</max_vel>
                <min_depth>0</min_depth>
              </ode>
              <bullet>
                <split_impulse>1</split_impulse>
                <split_impulse_penetration_threshold>-0.01</split_impulse_penetration_threshold>
                <soft_cfm>0</soft_cfm>
                <soft_erp>0.2</soft_erp>
                <kp>1e+13</kp>
                <kd>1</kd>
              </bullet>
            </contact>
          </surface>
        </collision>
      </link>
      <link name='link_0_clone_1'>
        <inertial>
          <mass>1e+10</mass>
          <inertia>
            <ixx>3.11188e+07</ixx>
            <ixy>0</ixy>
            <ixz>0</ixz>
            <iyy>3.11188e+07</iyy>
            <iyz>0</iyz>
            <izz>1.00639e+07</izz>
          </inertia>
          <pose>0 0 0 0 -0 0</pose>
        </inertial>
        <pose>-0.076096 0.175363 0 0 -0 0</pose>
        <gravity>1</gravity>
        <self_collide>0</self_collide>
        <kinematic>0</kinematic>
        <enable_wind>0</enable_wind>
        <visual name='visual'>
          <pose>0 0 0 0 -0 0</pose>
          <geometry>
            <cylinder>
              <radius>0.0448636</radius>
              <length>0.17693</length>
            </cylinder>
          </geometry>
          <material>
            <lighting>1</lighting>
            <script>
              <uri>file://media/materials/scripts/gazebo.material</uri>
              <name>Gazebo/Red</name>
            </script>
            <shader type='pixel'>
              <normal_map>__default__</normal_map>
            </shader>
            <ambient>1 0 0 1</ambient>
            <diffuse>1 0 0 1</diffuse>
            <specular>0.1 0.1 0.1 1</specular>
            <emissive>0 0 0 1</emissive>
          </material>
          <transparency>0</transparency>
          <cast_shadows>1</cast_shadows>
        </visual>
        <collision name='collision'>
          <laser_retro>0</laser_retro>
          <max_contacts>10</max_contacts>
          <pose>0 0 0 0 -0 0</pose>
          <geometry>
            <cylinder>
              <radius>0.044864</radius>
              <length>0.17693</length>
            </cylinder>
          </geometry>
          <surface>
            <friction>
              <ode>
                <mu>1</mu>
                <mu2>1</mu2>
                <fdir1>0 0 0</fdir1>
                <slip1>0</slip1>
                <slip2>0</slip2>
              </ode>
              <torsional>
                <coefficient>1</coefficient>
                <patch_radius>0</patch_radius>
                <surface_radius>0</surface_radius>
                <use_patch_radius>1</use_patch_radius>
                <ode>
                  <slip>0</slip>
                </ode>
              </torsional>
            </friction>
            <bounce>
              <restitution_coefficient>0</restitution_coefficient>
              <threshold>1e+06</threshold>
            </bounce>
            <contact>
              <collide_without_contact>0</collide_without_contact>
              <collide_without_contact_bitmask>1</collide_without_contact_bitmask>
              <collide_bitmask>1</collide_bitmask>
              <ode>
                <soft_cfm>0</soft_cfm>
                <soft_erp>0.2</soft_erp>
                <kp>1e+13</kp>
                <kd>1</kd>
                <max_vel>0.01</max_vel>
                <min_depth>0</min_depth>
              </ode>
              <bullet>
                <split_impulse>1</split_impulse>
                <split_impulse_penetration_threshold>-0.01</split_impulse_penetration_threshold>
                <soft_cfm>0</soft_cfm>
                <soft_erp>0.2</soft_erp>
                <kp>1e+13</kp>
                <kd>1</kd>
              </bullet>
            </contact>
          </surface>
        </collision>
      </link>
      <link name='link_0_clone_1_clone'>
        <inertial>
          <mass>1e+10</mass>
          <inertia>
            <ixx>3.11188e+07</ixx>
            <ixy>0</ixy>
            <ixz>0</ixz>
            <iyy>3.11188e+07</iyy>
            <iyz>0</iyz>
            <izz>1.00639e+07</izz>
          </inertia>
          <pose>0 0 0 0 -0 0</pose>
        </inertial>
        <pose>0.08216 0.531048 0 0 -0 0</pose>
        <gravity>1</gravity>
        <self_collide>0</self_collide>
        <kinematic>0</kinematic>
        <enable_wind>0</enable_wind>
        <visual name='visual'>
          <pose>0 0 0 0 -0 0</pose>
          <geometry>
            <cylinder>
              <radius>0.0448636</radius>
              <length>0.17693</length>
            </cylinder>
          </geometry>
          <material>
            <lighting>1</lighting>
            <script>
              <uri>file://media/materials/scripts/gazebo.material</uri>
              <name>Gazebo/Red</name>
            </script>
            <shader type='pixel'>
              <normal_map>__default__</normal_map>
            </shader>
            <ambient>1 0 0 1</ambient>
            <diffuse>1 0 0 1</diffuse>
            <specular>0.1 0.1 0.1 1</specular>
            <emissive>0 0 0 1</emissive>
          </material>
          <transparency>0</transparency>
          <cast_shadows>1</cast_shadows>
        </visual>
        <collision name='collision'>
          <laser_retro>0</laser_retro>
          <max_contacts>10</max_contacts>
          <pose>0 0 0 0 -0 0</pose>
          <geometry>
            <cylinder>
              <radius>0.044864</radius>
              <length>0.17693</length>
            </cylinder>
          </geometry>
          <surface>
            <friction>
              <ode>
                <mu>1</mu>
                <mu2>1</mu2>
                <fdir1>0 0 0</fdir1>
                <slip1>0</slip1>
                <slip2>0</slip2>
              </ode>
              <torsional>
                <coefficient>1</coefficient>
                <patch_radius>0</patch_radius>
                <surface_radius>0</surface_radius>
                <use_patch_radius>1</use_patch_radius>
                <ode>
                  <slip>0</slip>
                </ode>
              </torsional>
            </friction>
            <bounce>
              <restitution_coefficient>0</restitution_coefficient>
              <threshold>1e+06</threshold>
            </bounce>
            <contact>
              <collide_without_contact>0</collide_without_contact>
              <collide_without_contact_bitmask>1</collide_without_contact_bitmask>
              <collide_bitmask>1</collide_bitmask>
              <ode>
                <soft_cfm>0</soft_cfm>
                <soft_erp>0.2</soft_erp>
                <kp>1e+13</kp>
                <kd>1</kd>
                <max_vel>0.01</max_vel>
                <min_depth>0</min_depth>
              </ode>
              <bullet>
                <split_impulse>1</split_impulse>
                <split_impulse_penetration_threshold>-0.01</split_impulse_penetration_threshold>
                <soft_cfm>0</soft_cfm>
                <soft_erp>0.2</soft_erp>
                <kp>1e+13</kp>
                <kd>1</kd>
              </bullet>
            </contact>
          </surface>
        </collision>
      </link>
      <link name='link_0_clone_1_clone_0'>
        <inertial>
          <mass>1e+10</mass>
          <inertia>
            <ixx>3.11188e+07</ixx>
            <ixy>0</ixy>
            <ixz>0</ixz>
            <iyy>3.11188e+07</iyy>
            <iyz>0</iyz>
            <izz>1.00639e+07</izz>
          </inertia>
          <pose>0 0 0 0 -0 0</pose>
        </inertial>
        <pose>-0.073268 0.8857 0 0 -0 0</pose>
        <gravity>1</gravity>
        <self_collide>0</self_collide>
        <kinematic>0</kinematic>
        <enable_wind>0</enable_wind>
        <visual name='visual'>
          <pose>0 0 0 0 -0 0</pose>
          <geometry>
            <cylinder>
              <radius>0.0448636</radius>
              <length>0.17693</length>
            </cylinder>
          </geometry>
          <material>
            <lighting>1</lighting>
            <script>
              <uri>file://media/materials/scripts/gazebo.material</uri>
              <name>Gazebo/Red</name>
            </script>
            <shader type='pixel'>
              <normal_map>__default__</normal_map>
            </shader>
            <ambient>1 0 0 1</ambient>
            <diffuse>1 0 0 1</diffuse>
            <specular>0.1 0.1 0.1 1</specular>
            <emissive>0 0 0 1</emissive>
          </material>
          <transparency>0</transparency>
          <cast_shadows>1</cast_shadows>
        </visual>
        <collision name='collision'>
          <laser_retro>0</laser_retro>
          <max_contacts>10</max_contacts>
          <pose>0 0 0 0 -0 0</pose>
          <geometry>
            <cylinder>
              <radius>0.044864</radius>
              <length>0.17693</length>
            </cylinder>
          </geometry>
          <surface>
            <friction>
              <ode>
                <mu>1</mu>
                <mu2>1</mu2>
                <fdir1>0 0 0</fdir1>
                <slip1>0</slip1>
                <slip2>0</slip2>
              </ode>
              <torsional>
                <coefficient>1</coefficient>
                <patch_radius>0</patch_radius>
                <surface_radius>0</surface_radius>
                <use_patch_radius>1</use_patch_radius>
                <ode>
                  <slip>0</slip>
                </ode>
              </torsional>
            </friction>
            <bounce>
              <restitution_coefficient>0</restitution_coefficient>
              <threshold>1e+06</threshold>
            </bounce>
            <contact>
              <collide_without_contact>0</collide_without_contact>
              <collide_without_contact_bitmask>1</collide_without_contact_bitmask>
              <collide_bitmask>1</collide_bitmask>
              <ode>
                <soft_cfm>0</soft_cfm>
                <soft_erp>0.2</soft_erp>
                <kp>1e+13</kp>
                <kd>1</kd>
                <max_vel>0.01</max_vel>
                <min_depth>0</min_depth>
              </ode>
              <bullet>
                <split_impulse>1</split_impulse>
                <split_impulse_penetration_threshold>-0.01</split_impulse_penetration_threshold>
                <soft_cfm>0</soft_cfm>
                <soft_erp>0.2</soft_erp>
                <kp>1e+13</kp>
                <kd>1</kd>
              </bullet>
            </contact>
          </surface>
        </collision>
      </link>
      <link name='link_0_clone_1_clone_1'>
        <inertial>
          <mass>1e+10</mass>
          <inertia>
            <ixx>3.11188e+07</ixx>
            <ixy>0</ixy>
            <ixz>0</ixz>
            <iyy>3.11188e+07</iyy>
            <iyz>0</iyz>
            <izz>1.00639e+07</izz>
          </inertia>
          <pose>0 0 0 0 -0 0</pose>
        </inertial>
        <pose>0.102666 1.23379 0 0 -0 0</pose>
        <gravity>1</gravity>
        <self_collide>0</self_collide>
        <kinematic>0</kinematic>
        <enable_wind>0</enable_wind>
        <visual name='visual'>
          <pose>0 0 0 0 -0 0</pose>
          <geometry>
            <cylinder>
              <radius>0.0448636</radius>
              <length>0.17693</length>
            </cylinder>
          </geometry>
          <material>
            <lighting>1</lighting>
            <script>
              <uri>file://media/materials/scripts/gazebo.material</uri>
              <name>Gazebo/Red</name>
            </script>
            <shader type='pixel'>
              <normal_map>__default__</normal_map>
            </shader>
            <ambient>1 0 0 1</ambient>
            <diffuse>1 0 0 1</diffuse>
            <specular>0.1 0.1 0.1 1</specular>
            <emissive>0 0 0 1</emissive>
          </material>
          <transparency>0</transparency>
          <cast_shadows>1</cast_shadows>
        </visual>
        <collision name='collision'>
          <laser_retro>0</laser_retro>
          <max_contacts>10</max_contacts>
          <pose>0 0 0 0 -0 0</pose>
          <geometry>
            <cylinder>
              <radius>0.044864</radius>
              <length>0.17693</length>
            </cylinder>
          </geometry>
          <surface>
            <friction>
              <ode>
                <mu>1</mu>
                <mu2>1</mu2>
                <fdir1>0 0 0</fdir1>
                <slip1>0</slip1>
                <slip2>0</slip2>
              </ode>
              <torsional>
                <coefficient>1</coefficient>
                <patch_radius>0</patch_radius>
                <surface_radius>0</surface_radius>
                <use_patch_radius>1</use_patch_radius>
                <ode>
                  <slip>0</slip>
                </ode>
              </torsional>
            </friction>
            <bounce>
              <restitution_coefficient>0</restitution_coefficient>
              <threshold>1e+06</threshold>
            </bounce>
            <contact>
              <collide_without_contact>0</collide_without_contact>
              <collide_without_contact_bitmask>1</collide_without_contact_bitmask>
              <collide_bitmask>1</collide_bitmask>
              <ode>
                <soft_cfm>0</soft_cfm>
                <soft_erp>0.2</soft_erp>
                <kp>1e+13</kp>
                <kd>1</kd>
                <max_vel>0.01</max_vel>
                <min_depth>0</min_depth>
              </ode>
              <bullet>
                <split_impulse>1</split_impulse>
                <split_impulse_penetration_threshold>-0.01</split_impulse_penetration_threshold>
                <soft_cfm>0</soft_cfm>
                <soft_erp>0.2</soft_erp>
                <kp>1e+13</kp>
                <kd>1</kd>
              </bullet>
            </contact>
          </surface>
        </collision>
      </link>
      <link name='link_0_clone_2'>
        <inertial>
          <mass>1e+10</mass>
          <inertia>
            <ixx>3.11188e+07</ixx>
            <ixy>0</ixy>
            <ixz>0</ixz>
            <iyy>3.11188e+07</iyy>
            <iyz>0</iyz>
            <izz>1.00639e+07</izz>
          </inertia>
          <pose>0 0 0 0 -0 0</pose>
        </inertial>
        <pose>-0.112564 -1.2271 0 0 -0 0</pose>
        <gravity>1</gravity>
        <self_collide>0</self_collide>
        <kinematic>0</kinematic>
        <enable_wind>0</enable_wind>
        <visual name='visual'>
          <pose>0 0 0 0 -0 0</pose>
          <geometry>
            <cylinder>
              <radius>0.0448636</radius>
              <length>0.17693</length>
            </cylinder>
          </geometry>
          <material>
            <lighting>1</lighting>
            <script>
              <uri>file://media/materials/scripts/gazebo.material</uri>
              <name>Gazebo/Red</name>
            </script>
            <shader type='pixel'>
              <normal_map>__default__</normal_map>
            </shader>
            <ambient>1 0 0 1</ambient>
            <diffuse>1 0 0 1</diffuse>
            <specular>0.1 0.1 0.1 1</specular>
            <emissive>0 0 0 1</emissive>
          </material>
          <transparency>0</transparency>
          <cast_shadows>1</cast_shadows>
        </visual>
        <collision name='collision'>
          <laser_retro>0</laser_retro>
          <max_contacts>10</max_contacts>
          <pose>0 0 0 0 -0 0</pose>
          <geometry>
            <cylinder>
              <radius>0.044864</radius>
              <length>0.17693</length>
            </cylinder>
          </geometry>
          <surface>
            <friction>
              <ode>
                <mu>1</mu>
                <mu2>1</mu2>
                <fdir1>0 0 0</fdir1>
                <slip1>0</slip1>
                <slip2>0</slip2>
              </ode>
              <torsional>
                <coefficient>1</coefficient>
                <patch_radius>0</patch_radius>
                <surface_radius>0</surface_radius>
                <use_patch_radius>1</use_patch_radius>
                <ode>
                  <slip>0</slip>
                </ode>
              </torsional>
            </friction>
            <bounce>
              <restitution_coefficient>0</restitution_coefficient>
              <threshold>1e+06</threshold>
            </bounce>
            <contact>
              <collide_without_contact>0</collide_without_contact>
              <collide_without_contact_bitmask>1</collide_without_contact_bitmask>
              <collide_bitmask>1</collide_bitmask>
              <ode>
                <soft_cfm>0</soft_cfm>
                <soft_erp>0.2</soft_erp>
                <kp>1e+13</kp>
                <kd>1</kd>
                <max_vel>0.01</max_vel>
                <min_depth>0</min_depth>
              </ode>
              <bullet>
                <split_impulse>1</split_impulse>
                <split_impulse_penetration_threshold>-0.01</split_impulse_penetration_threshold>
                <soft_cfm>0</soft_cfm>
                <soft_erp>0.2</soft_erp>
                <kp>1e+13</kp>
                <kd>1</kd>
              </bullet>
            </contact>
          </surface>
        </collision>
      </link>
      <static>1</static>
      <allow_auto_disable>1</allow_auto_disable>
      <pose>0.008468 0.817097 0.088981 0 -0 0</pose>
    </model>
  </world>
</sdf>
