<sdf version='1.7'>
  <world name='default'>
    <light name='sun' type='directional'>
      <cast_shadows>1</cast_shadows>
      <pose>0 0 10 0 -0 0</pose>
      <diffuse>0.8 0.8 0.8 1</diffuse>
      <specular>0.2 0.2 0.2 1</specular>
      <attenuation>
        <range>1000</range>
        <constant>0.9</constant>
        <linear>0.01</linear>
        <quadratic>0.001</quadratic>
      </attenuation>
      <direction>-0.5 0.1 -0.9</direction>
      <spot>
        <inner_angle>0</inner_angle>
        <outer_angle>0</outer_angle>
        <falloff>0</falloff>
      </spot>
    </light>
    <model name='ground_plane'>
      <static>1</static>
      <link name='link'>
        <collision name='collision'>
          <geometry>
            <plane>
              <normal>0 0 1</normal>
              <size>100 100</size>
            </plane>
          </geometry>
          <surface>
            <contact>
              <collide_bitmask>65535</collide_bitmask>
              <ode/>
            </contact>
            <friction>
              <ode>
                <mu>100</mu>
                <mu2>50</mu2>
              </ode>
              <torsional>
                <ode/>
              </torsional>
            </friction>
            <bounce/>
          </surface>
          <max_contacts>10</max_contacts>
        </collision>
        <visual name='visual'>
          <cast_shadows>0</cast_shadows>
          <geometry>
            <plane>
              <normal>0 0 1</normal>
              <size>100 100</size>
            </plane>
          </geometry>
          <material>
            <script>
              <uri>file://media/materials/scripts/gazebo.material</uri>
              <name>Gazebo/Grey</name>
            </script>
          </material>
        </visual>
        <self_collide>0</self_collide>
        <enable_wind>0</enable_wind>
        <kinematic>0</kinematic>
      </link>
    </model>
    <gravity>0 0 -9.8</gravity>
    <magnetic_field>6e-06 2.3e-05 -4.2e-05</magnetic_field>
    <atmosphere type='adiabatic'/>
    <physics type='ode'>
      <max_step_size>0.001</max_step_size>
      <real_time_factor>1</real_time_factor>
      <real_time_update_rate>1000</real_time_update_rate>
    </physics>
    <scene>
      <ambient>0.4 0.4 0.4 1</ambient>
      <background>0.7 0.7 0.7 1</background>
      <shadows>1</shadows>
    </scene>
    <audio>
      <device>default</device>
    </audio>
    <wind/>
    <spherical_coordinates>
      <surface_model>EARTH_WGS84</surface_model>
      <latitude_deg>0</latitude_deg>
      <longitude_deg>0</longitude_deg>
      <elevation>0</elevation>
      <heading_deg>0</heading_deg>
    </spherical_coordinates>
    <model name='obstacle_1'>
      <link name='base'>
        <inertial>
          <mass>500</mass>
          <inertia>
            <ixx>0.0386667</ixx>
            <ixy>2.77556e-17</ixy>
            <ixz>0</ixz>
            <iyy>0.012</iyy>
            <iyz>0</iyz>
            <izz>0.0386667</izz>
          </inertia>
          <pose>0 0 0 0 -0 0</pose>
        </inertial>
        <collision name='base_fixed_joint_lump__obs_1_collision'>
          <geometry>
            <box>
              <size>0.01 0.01 0.1</size>
            </box>
          </geometry>
          <max_contacts>10</max_contacts>
          <surface>
            <contact>
              <ode/>
            </contact>
            <bounce/>
            <friction>
              <torsional>
                <ode/>
              </torsional>
              <ode/>
            </friction>
          </surface>
        </collision>
        <visual name='base_fixed_joint_lump__obs_1_visual'>
          <geometry>
            <box>
              <size>0.01 0.01 0.1</size>
            </box>
          </geometry>
        </visual>
        <self_collide>0</self_collide>
        <enable_wind>0</enable_wind>
        <kinematic>0</kinematic>
      </link>
      <pose>0.05 0.245 0 0 -0 0</pose>
    </model>
    <model name='obstacle_2'>
      <link name='base'>
        <inertial>
          <mass>500</mass>
          <inertia>
            <ixx>0.0386667</ixx>
            <ixy>2.77556e-17</ixy>
            <ixz>0</ixz>
            <iyy>0.012</iyy>
            <iyz>0</iyz>
            <izz>0.0386667</izz>
          </inertia>
          <pose>0 0 0 0 -0 0</pose>
        </inertial>
        <collision name='base_fixed_joint_lump__obs_1_collision'>
          <geometry>
            <box>
              <size>0.01 0.01 0.1</size>
            </box>
          </geometry>
          <max_contacts>10</max_contacts>
          <surface>
            <contact>
              <ode/>
            </contact>
            <bounce/>
            <friction>
              <torsional>
                <ode/>
              </torsional>
              <ode/>
            </friction>
          </surface>
        </collision>
        <visual name='base_fixed_joint_lump__obs_1_visual'>
          <geometry>
            <box>
              <size>0.01 0.01 0.1</size>
            </box>
          </geometry>
        </visual>
        <self_collide>0</self_collide>
        <enable_wind>0</enable_wind>
        <kinematic>0</kinematic>
      </link>
      <pose>-0.05 0.245 0 0 -0 0</pose>
    </model>
    <model name='obstacle_3'>
      <link name='base'>
        <inertial>
          <mass>500</mass>
          <inertia>
            <ixx>0.0386667</ixx>
            <ixy>2.77556e-17</ixy>
            <ixz>0</ixz>
            <iyy>0.012</iyy>
            <iyz>0</iyz>
            <izz>0.0386667</izz>
          </inertia>
          <pose>0 0 0 0 -0 0</pose>
        </inertial>
        <collision name='base_fixed_joint_lump__obs_1_collision'>
          <geometry>
            <box>
              <size>0.01 0.01 0.1</size>
            </box>
          </geometry>
          <max_contacts>10</max_contacts>
          <surface>
            <contact>
              <ode/>
            </contact>
            <bounce/>
            <friction>
              <torsional>
                <ode/>
              </torsional>
              <ode/>
            </friction>
          </surface>
        </collision>
        <visual name='base_fixed_joint_lump__obs_1_visual'>
          <geometry>
            <box>
              <size>0.01 0.01 0.1</size>
            </box>
          </geometry>
        </visual>
        <self_collide>0</self_collide>
        <enable_wind>0</enable_wind>
        <kinematic>0</kinematic>
      </link>
      <pose>0.06 0.5 0 0 -0 0</pose>
    </model>
    <model name='obstacle_4'>
      <link name='base'>
        <inertial>
          <mass>500</mass>
          <inertia>
            <ixx>0.0386667</ixx>
            <ixy>2.77556e-17</ixy>
            <ixz>0</ixz>
            <iyy>0.012</iyy>
            <iyz>0</iyz>
            <izz>0.0386667</izz>
          </inertia>
          <pose>0 0 0 0 -0 0</pose>
        </inertial>
        <collision name='base_fixed_joint_lump__obs_1_collision'>
          <geometry>
            <box>
              <size>0.01 0.01 0.1</size>
            </box>
          </geometry>
          <max_contacts>10</max_contacts>
          <surface>
            <contact>
              <ode/>
            </contact>
            <bounce/>
            <friction>
              <torsional>
                <ode/>
              </torsional>
              <ode/>
            </friction>
          </surface>
        </collision>
        <visual name='base_fixed_joint_lump__obs_1_visual'>
          <geometry>
            <box>
              <size>0.01 0.01 0.1</size>
            </box>
          </geometry>
        </visual>
        <self_collide>0</self_collide>
        <enable_wind>0</enable_wind>
        <kinematic>0</kinematic>
      </link>
      <pose>-0.06 0.5 0 0 -0 0</pose>
    </model>
    <model name='obstacle_5'>
      <link name='base'>
        <inertial>
          <mass>500</mass>
          <inertia>
            <ixx>0.0386667</ixx>
            <ixy>2.77556e-17</ixy>
            <ixz>0</ixz>
            <iyy>0.012</iyy>
            <iyz>0</iyz>
            <izz>0.0386667</izz>
          </inertia>
          <pose>0 0 0 0 -0 0</pose>
        </inertial>
        <collision name='base_fixed_joint_lump__obs_1_collision'>
          <geometry>
            <box>
              <size>0.01 0.01 0.1</size>
            </box>
          </geometry>
          <max_contacts>10</max_contacts>
          <surface>
            <contact>
              <ode/>
            </contact>
            <bounce/>
            <friction>
              <torsional>
                <ode/>
              </torsional>
              <ode/>
            </friction>
          </surface>
        </collision>
        <visual name='base_fixed_joint_lump__obs_1_visual'>
          <geometry>
            <box>
              <size>0.01 0.01 0.1</size>
            </box>
          </geometry>
        </visual>
        <self_collide>0</self_collide>
        <enable_wind>0</enable_wind>
        <kinematic>0</kinematic>
      </link>
      <pose>0.06 0.75 0 0 -0 0</pose>
    </model>
    <model name='obstacle_6'>
      <link name='base'>
        <inertial>
          <mass>500</mass>
          <inertia>
            <ixx>0.0386667</ixx>
            <ixy>2.77556e-17</ixy>
            <ixz>0</ixz>
            <iyy>0.012</iyy>
            <iyz>0</iyz>
            <izz>0.0386667</izz>
          </inertia>
          <pose>0 0 0 0 -0 0</pose>
        </inertial>
        <collision name='base_fixed_joint_lump__obs_1_collision'>
          <geometry>
            <box>
              <size>0.01 0.01 0.1</size>
            </box>
          </geometry>
          <max_contacts>10</max_contacts>
          <surface>
            <contact>
              <ode/>
            </contact>
            <bounce/>
            <friction>
              <torsional>
                <ode/>
              </torsional>
              <ode/>
            </friction>
          </surface>
        </collision>
        <visual name='base_fixed_joint_lump__obs_1_visual'>
          <geometry>
            <box>
              <size>0.01 0.01 0.1</size>
            </box>
          </geometry>
        </visual>
        <self_collide>0</self_collide>
        <enable_wind>0</enable_wind>
        <kinematic>0</kinematic>
      </link>
      <pose>-0.06 0.75 0 0 -0 0</pose>
    </model>
    <state world_name='default'>
      <sim_time>983 919000000</sim_time>
      <real_time>822 949100753</real_time>
      <wall_time>1713793462 503600268</wall_time>
      <iterations>810108</iterations>
      <model name='ground_plane'>
        <pose>0 0 0 0 -0 0</pose>
        <scale>1 1 1</scale>
        <link name='link'>
          <pose>0 0 0 0 -0 0</pose>
          <velocity>0 0 0 0 -0 0</velocity>
          <acceleration>0 0 0 0 -0 0</acceleration>
          <wrench>0 0 0 0 -0 0</wrench>
        </link>
      </model>
      <model name='my_bot'>
        <pose>-0.000726 -0.020811 -2e-06 6e-06 -0 -0.010374</pose>
        <scale>1 1 1</scale>
        <link name='base_link'>
          <pose>-0.000726 -0.020811 -2e-06 6e-06 -0 -0.010374</pose>
          <velocity>0.000194 -0.000422 -0.002348 0.006331 -0.000563 0.002514</velocity>
          <acceleration>-0.044619 -0.582888 -1.94037 -0.813239 -0.760771 2.09481</acceleration>
          <wrench>-0.044619 -0.582888 -1.94037 0 -0 0</wrench>
        </link>
        <link name='link_10'>
          <pose>0.000753 1.55418 0 -2e-06 2e-06 -0.005671</pose>
          <velocity>0.000125 -4e-06 1.5e-05 0.000664 -1.8e-05 0.000807</velocity>
          <acceleration>-0.878511 0.329886 0.088218 1.83564 -0.873222 0.329355</acceleration>
          <wrench>-0.878511 0.329886 0.088218 0 -0 0</wrench>
        </link>
        <link name='link_2'>
          <pose>0.001089 0.15418 -1e-06 1.1e-05 -2e-06 0.000783</pose>
          <velocity>-5.8e-05 1e-06 -0.001447 0.011713 -0.002304 -0.000374</velocity>
          <acceleration>-0.059732 -0.35053 -0.650425 -0.833591 -0.949522 -0.374866</acceleration>
          <wrench>-0.059732 -0.35053 -0.650425 0 -0 0</wrench>
        </link>
        <link name='link_3'>
          <pose>0.000952 0.32918 0 6e-06 1e-06 0.000875</pose>
          <velocity>1e-06 7e-05 3.8e-05 0.005837 0.001095 0.002288</velocity>
          <acceleration>-0.08243 -0.086923 0.425134 2.07998 0.578122 -0.8533</acceleration>
          <wrench>-0.08243 -0.086923 0.425134 0 -0 0</wrench>
        </link>
        <link name='link_4'>
          <pose>0.000799 0.50418 1e-06 2e-06 2e-06 0.002264</pose>
          <velocity>-0.000349 0.000182 0.000586 0.001483 -1.3e-05 -0.00026</velocity>
          <acceleration>-0.142296 0.189671 0.712327 1.78333 1.39189 -2.33302</acceleration>
          <wrench>-0.142296 0.189671 0.712327 0 -0 0</wrench>
        </link>
        <link name='link_5'>
          <pose>0.000403 0.67918 1e-06 -1e-06 3e-06 -0.000629</pose>
          <velocity>-0.000358 0.000174 0.000549 -0.001908 -0.000296 -0.002251</velocity>
          <acceleration>0.063813 0.263292 0.421066 -1.93783 1.07192 0.768091</acceleration>
          <wrench>0.063813 0.263292 0.421066 0 -0 0</wrench>
        </link>
        <link name='link_6'>
          <pose>0.000513 0.85418 -0 1e-06 -1e-06 0.00078</pose>
          <velocity>-1.3e-05 -4e-06 2.1e-05 -0.001912 -0.001976 0.000857</velocity>
          <acceleration>-0.181063 0.072374 -0.163149 0.552092 -0.717987 -1.86675</acceleration>
          <wrench>-0.181063 0.072374 -0.163149 0 -0 0</wrench>
        </link>
        <link name='link_7'>
          <pose>0.000376 1.02918 0 -1e-06 6e-06 -0.00076</pose>
          <velocity>-0.000197 4e-05 -0.00019 0.00122 -0.002902 -0.001396</velocity>
          <acceleration>-0.308109 0.108257 -0.159198 0.557155 -0.220175 2.02703</acceleration>
          <wrench>-0.308109 0.108257 -0.159198 0 -0 0</wrench>
        </link>
        <link name='link_8'>
          <pose>0.000508 1.20418 0 2e-06 -1e-06 -0.001044</pose>
          <velocity>3e-06 -0.00013 0.000165 -0.000677 0.001642 -0.004424</velocity>
          <acceleration>0.310576 -0.038789 -0.010816 1.61401 0.393067 0.031075</acceleration>
          <wrench>0.310576 -0.038789 -0.010816 0 -0 0</wrench>
        </link>
        <link name='link_9'>
          <pose>0.000691 1.37918 0 -0 -3e-06 -0.000357</pose>
          <velocity>0.000831 -8.4e-05 8.9e-05 -7.6e-05 0.000798 0.00391</velocity>
          <acceleration>-0.162867 0.193239 0.099752 0.572005 -0.657395 1.28304</acceleration>
          <wrench>-0.162867 0.193239 0.099752 0 -0 0</wrench>
        </link>
      </model>
      <model name='obstacle_1'>
        <pose>0.485477 0.23275 0.05 -1e-06 3e-06 -0.059636</pose>
        <scale>1 1 1</scale>
        <link name='base'>
          <pose>0.485477 0.23275 0.05 -1e-06 3e-06 -0.059636</pose>
          <velocity>0 0 0 0 -0 0</velocity>
          <acceleration>0.988402 0.319726 -0.031096 -2.31777 -0.386321 -1.11218</acceleration>
          <wrench>494.201 159.863 -15.548 0 -0 0</wrench>
        </link>
      </model>
      <model name='obstacle_2'>
        <pose>-0.505278 0.256568 0.05 -4e-06 1.8e-05 -0.058457</pose>
        <scale>1 1 1</scale>
        <link name='base'>
          <pose>-0.505278 0.256568 0.05 -4e-06 1.8e-05 -0.058457</pose>
          <velocity>0 0 0 0 -0 0</velocity>
          <acceleration>-0.946418 0.454596 0.001471 1.93556 0.323206 -1.76506</acceleration>
          <wrench>-473.209 227.298 0.73533 0 -0 0</wrench>
        </link>
      </model>
      <model name='obstacle_3'>
        <pose>0.48854 0.49998 0.05 4e-06 1.8e-05 0.027303</pose>
        <scale>1 1 1</scale>
        <link name='base'>
          <pose>0.48854 0.49998 0.05 4e-06 1.8e-05 0.027303</pose>
          <velocity>0 0 0 0 -0 0</velocity>
          <acceleration>-0.961689 -0.390515 0.008422 2.81246 0.5802 -2.02815</acceleration>
          <wrench>-480.844 -195.257 4.21113 0 -0 0</wrench>
        </link>
      </model>
      <model name='obstacle_4'>
        <pose>-0.540859 0.498357 0.05 4e-06 -1.8e-05 -0.03803</pose>
        <scale>1 1 1</scale>
        <link name='base'>
          <pose>-0.540859 0.498357 0.05 4e-06 -1.8e-05 -0.03803</pose>
          <velocity>0 0 0 0 -0 0</velocity>
          <acceleration>0.956548 -0.415412 0.004767 -2.89295 -0.51233 3.07123</acceleration>
          <wrench>478.274 -207.706 2.38354 0 -0 0</wrench>
        </link>
      </model>
      <model name='obstacle_5'>
        <pose>0.5347 0.675072 0.05 9e-06 2e-06 -0.26223</pose>
        <scale>1 1 1</scale>
        <link name='base'>
          <pose>0.5347 0.675072 0.05 9e-06 2e-06 -0.26223</pose>
          <velocity>0 0 0 0 -0 0</velocity>
          <acceleration>-0.170707 -0.929089 -0.095387 -1.0121 1.3868 1.23907</acceleration>
          <wrench>-85.3534 -464.544 -47.6935 0 -0 0</wrench>
        </link>
      </model>
      <model name='obstacle_6'>
        <pose>-0.568573 0.748749 0.05 -5e-06 -2.1e-05 4.1e-05</pose>
        <scale>1 1 1</scale>
        <link name='base'>
          <pose>-0.568573 0.748749 0.05 -5e-06 -2.1e-05 4.1e-05</pose>
          <velocity>0 0 0 0 -0 0</velocity>
          <acceleration>0.389192 -0.590322 0.246736 1.29496 -0.763441 1.27755</acceleration>
          <wrench>194.596 -295.161 123.368 0 -0 0</wrench>
        </link>
      </model>
      <model name='unit_cylinder'>
        <pose>0.08485 0.063589 0.069857 0 -0 1.7e-05</pose>
        <scale>0.102578 0.102578 0.139726</scale>
        <link name='link'>
          <pose>0.08485 0.063589 0.069857 0 -0 1.7e-05</pose>
          <velocity>0 0 0 0 -0 0</velocity>
          <acceleration>0 0 -9.8 0 -0 0</acceleration>
          <wrench>0 0 -9.8 0 -0 0</wrench>
        </link>
      </model>
      <model name='unit_cylinder_clone'>
        <pose>-0.079603 0.320485 0.069854 0 -0 4.8e-05</pose>
        <scale>1 1 1</scale>
        <link name='link'>
          <pose>-0.079603 0.320485 0.069854 0 -0 4.8e-05</pose>
          <velocity>0 0 0 0 -0 0</velocity>
          <acceleration>-0.443637 0.025278 -9.36702 0.037852 0.062443 0.040995</acceleration>
          <wrench>-0.443637 0.025278 -9.36702 0 -0 0</wrench>
        </link>
      </model>
      <model name='unit_cylinder_clone_0'>
        <pose>-0.083684 -0.172888 0.069857 0 -0 1.7e-05</pose>
        <scale>1 1 1</scale>
        <link name='link'>
          <pose>-0.083684 -0.172888 0.069857 0 -0 1.7e-05</pose>
          <velocity>0 0 0 0 -0 0</velocity>
          <acceleration>0 0 -9.8 0 -0 0</acceleration>
          <wrench>0 0 -9.8 0 -0 0</wrench>
        </link>
      </model>
      <model name='unit_cylinder_clone_clone'>
        <pose>0.084982 0.558164 0.069854 0 -0 0.000145</pose>
        <scale>1 1 1</scale>
        <link name='link'>
          <pose>0.084982 0.558164 0.069854 0 -0 0.000145</pose>
          <velocity>0 0 0 0 -0 0</velocity>
          <acceleration>0 0 -9.8 0 -0 0</acceleration>
          <wrench>0 0 -9.8 0 -0 0</wrench>
        </link>
      </model>
      <model name='unit_cylinder_clone_clone_clone'>
        <pose>-0.082818 0.857604 0.069854 0 -0 0.000144</pose>
        <scale>1 1 1</scale>
        <link name='link'>
          <pose>-0.082818 0.857604 0.069854 0 -0 0.000144</pose>
          <velocity>0 0 0 0 -0 0</velocity>
          <acceleration>0 0 -9.8 0 -0 0</acceleration>
          <wrench>0 0 -9.8 0 -0 0</wrench>
        </link>
      </model>
      <model name='unit_cylinder_clone_clone_clone_clone'>
        <pose>0.085755 1.14376 0.069854 0 -0 0.000144</pose>
        <scale>1 1 1</scale>
        <link name='link'>
          <pose>0.085755 1.14376 0.069854 0 -0 0.000144</pose>
          <velocity>0 0 0 0 -0 0</velocity>
          <acceleration>0 0 -9.8 0 -0 0</acceleration>
          <wrench>0 0 -9.8 0 -0 0</wrench>
        </link>
      </model>
      <model name='unit_cylinder_clone_clone_clone_clone_clone'>
        <pose>-0.084513 1.45643 0.069859 -1e-06 1e-06 0.000147</pose>
        <scale>1 1 1</scale>
        <link name='link'>
          <pose>-0.084513 1.45643 0.069859 -1e-06 1e-06 0.000147</pose>
          <velocity>0 0 0 0 -0 0</velocity>
          <acceleration>0 0 -9.8 -0 -0 -0</acceleration>
          <wrench>0 0 -9.8 0 -0 0</wrench>
        </link>
      </model>
      <model name='unit_cylinder_clone_clone_clone_clone_clone_clone'>
        <pose>0.083557 1.72166 0.069854 -2e-06 -1e-06 0.000148</pose>
        <scale>1 1 1</scale>
        <link name='link'>
          <pose>0.083557 1.72166 0.069854 -2e-06 -1e-06 0.000148</pose>
          <velocity>0 0 0 0 -0 0</velocity>
          <acceleration>0 0 -9.8 0 -0 0</acceleration>
          <wrench>0 0 -9.8 0 -0 0</wrench>
        </link>
      </model>
      <light name='sun'>
        <pose>0 0 10 0 -0 0</pose>
      </light>
    </state>
    <gui fullscreen='0'>
      <camera name='user_camera'>
        <pose>0.025568 -0.136562 1.14368 0 1.4058 1.58419</pose>
        <view_controller>orbit</view_controller>
        <projection_type>perspective</projection_type>
      </camera>
    </gui>
    <model name='my_bot'>
      <link name='base_link'>
        <inertial>
          <pose>0 0.07 0.03 0 -0 0</pose>
          <mass>1</mass>
          <inertia>
            <ixx>0.00193333</ixx>
            <ixy>0</ixy>
            <ixz>0</ixz>
            <iyy>0.0006</iyy>
            <iyz>0</iyz>
            <izz>0.00193333</izz>
          </inertia>
        </inertial>
        <collision name='base_link_fixed_joint_lump__link_1_collision'>
          <pose>0 0.07 0.03 0 -0 0</pose>
          <geometry>
            <box>
              <size>0.06 0.14 0.06</size>
            </box>
          </geometry>
          <surface>
            <contact>
              <ode/>
            </contact>
            <friction>
              <ode/>
              <torsional>
                <ode/>
              </torsional>
            </friction>
            <bounce/>
          </surface>
          <max_contacts>10</max_contacts>
        </collision>
        <visual name='base_link_fixed_joint_lump__link_1_visual'>
          <pose>0 0.07 0.03 0 -0 0</pose>
          <geometry>
            <box>
              <size>0.06 0.14 0.06</size>
            </box>
          </geometry>
          <material>
            <script>
              <name>Gazebo/Green</name>
              <uri>file://media/materials/scripts/gazebo.material</uri>
            </script>
          </material>
        </visual>
        <visual name='base_link_fixed_joint_lump__camera_link_visual_1'>
          <pose>0 0 0.03 0 0 -1.5708</pose>
          <geometry>
            <box>
              <size>0.01 0.01 0.01</size>
            </box>
          </geometry>
          <material>
            <script>
              <name>Gazebo/Red</name>
              <uri>file://media/materials/scripts/gazebo.material</uri>
            </script>
          </material>
        </visual>
        <sensor name='camera' type='camera'>
          <visualize>1</visualize>
          <update_rate>10</update_rate>
          <camera>
            <horizontal_fov>1.089</horizontal_fov>
            <image>
              <format>R8G8B8</format>
              <width>640</width>
              <height>480</height>
            </image>
            <clip>
              <near>0.05</near>
              <far>8</far>
            </clip>
          </camera>
          <plugin name='camera_controller' filename='libgazebo_ros_camera.so'>
            <frame_name>camera_link_optical</frame_name>
          </plugin>
          <pose>0 0 0.03 0 0 -1.5708</pose>
        </sensor>
        <self_collide>0</self_collide>
        <enable_wind>0</enable_wind>
        <kinematic>0</kinematic>
      </link>
      <joint name='link_1_2_joint' type='revolute'>
        <pose relative_to='base_link'>0 0.175 0 0 -0 0</pose>
        <parent>base_link</parent>
        <child>link_2</child>
        <axis>
          <xyz>0 0 1</xyz>
          <limit>
            <lower>-0.785398</lower>
            <upper>0.785398</upper>
            <effort>1000</effort>
            <velocity>50</velocity>
          </limit>
          <dynamics>
            <spring_reference>0</spring_reference>
            <spring_stiffness>0</spring_stiffness>
          </dynamics>
        </axis>
      </joint>
      <link name='link_2'>
        <pose relative_to='link_1_2_joint'>0 0 0 0 -0 0</pose>
        <inertial>
          <pose>0 0.07 0.03 0 -0 0</pose>
          <mass>1</mass>
          <inertia>
            <ixx>0.00193333</ixx>
            <ixy>0</ixy>
            <ixz>0</ixz>
            <iyy>0.0006</iyy>
            <iyz>0</iyz>
            <izz>0.00193333</izz>
          </inertia>
        </inertial>
        <collision name='link_2_collision'>
          <pose>0 0.07 0.03 0 -0 0</pose>
          <geometry>
            <box>
              <size>0.06 0.14 0.06</size>
            </box>
          </geometry>
          <surface>
            <contact>
              <ode/>
            </contact>
            <friction>
              <ode/>
              <torsional>
                <ode/>
              </torsional>
            </friction>
            <bounce/>
          </surface>
          <max_contacts>10</max_contacts>
        </collision>
        <visual name='link_2_visual'>
          <pose>0 0.07 0.03 0 -0 0</pose>
          <geometry>
            <box>
              <size>0.06 0.14 0.06</size>
            </box>
          </geometry>
          <material>
            <script>
              <name>Gazebo/Blue</name>
              <uri>file://media/materials/scripts/gazebo.material</uri>
            </script>
          </material>
        </visual>
        <self_collide>0</self_collide>
        <enable_wind>0</enable_wind>
        <kinematic>0</kinematic>
      </link>
      <joint name='link_2_3_joint' type='revolute'>
        <pose relative_to='link_2'>0 0.175 0 0 -0 0</pose>
        <parent>link_2</parent>
        <child>link_3</child>
        <axis>
          <xyz>0 0 1</xyz>
          <limit>
            <lower>-0.785398</lower>
            <upper>0.785398</upper>
            <effort>1000</effort>
            <velocity>50</velocity>
          </limit>
          <dynamics>
            <spring_reference>0</spring_reference>
            <spring_stiffness>0</spring_stiffness>
          </dynamics>
        </axis>
      </joint>
      <link name='link_3'>
        <pose relative_to='link_2_3_joint'>0 0 0 0 -0 0</pose>
        <inertial>
          <pose>0 0.07 0.03 0 -0 0</pose>
          <mass>1</mass>
          <inertia>
            <ixx>0.00193333</ixx>
            <ixy>0</ixy>
            <ixz>0</ixz>
            <iyy>0.0006</iyy>
            <iyz>0</iyz>
            <izz>0.00193333</izz>
          </inertia>
        </inertial>
        <collision name='link_3_collision'>
          <pose>0 0.07 0.03 0 -0 0</pose>
          <geometry>
            <box>
              <size>0.06 0.14 0.06</size>
            </box>
          </geometry>
          <surface>
            <contact>
              <ode/>
            </contact>
            <friction>
              <ode/>
              <torsional>
                <ode/>
              </torsional>
            </friction>
            <bounce/>
          </surface>
          <max_contacts>10</max_contacts>
        </collision>
        <visual name='link_3_visual'>
          <pose>0 0.07 0.03 0 -0 0</pose>
          <geometry>
            <box>
              <size>0.06 0.14 0.06</size>
            </box>
          </geometry>
          <material>
            <script>
              <name>Gazebo/Orange</name>
              <uri>file://media/materials/scripts/gazebo.material</uri>
            </script>
          </material>
        </visual>
        <self_collide>0</self_collide>
        <enable_wind>0</enable_wind>
        <kinematic>0</kinematic>
      </link>
      <joint name='link_3_4_joint' type='revolute'>
        <pose relative_to='link_3'>0 0.175 0 0 -0 0</pose>
        <parent>link_3</parent>
        <child>link_4</child>
        <axis>
          <xyz>0 0 1</xyz>
          <limit>
            <lower>-0.785398</lower>
            <upper>0.785398</upper>
            <effort>1000</effort>
            <velocity>50</velocity>
          </limit>
          <dynamics>
            <spring_reference>0</spring_reference>
            <spring_stiffness>0</spring_stiffness>
          </dynamics>
        </axis>
      </joint>
      <link name='link_4'>
        <pose relative_to='link_3_4_joint'>0 0 0 0 -0 0</pose>
        <inertial>
          <pose>0 0.07 0.03 0 -0 0</pose>
          <mass>1</mass>
          <inertia>
            <ixx>0.00193333</ixx>
            <ixy>0</ixy>
            <ixz>0</ixz>
            <iyy>0.0006</iyy>
            <iyz>0</iyz>
            <izz>0.00193333</izz>
          </inertia>
        </inertial>
        <collision name='link_4_collision'>
          <pose>0 0.07 0.03 0 -0 0</pose>
          <geometry>
            <box>
              <size>0.06 0.14 0.06</size>
            </box>
          </geometry>
          <surface>
            <contact>
              <ode/>
            </contact>
            <friction>
              <ode/>
              <torsional>
                <ode/>
              </torsional>
            </friction>
            <bounce/>
          </surface>
          <max_contacts>10</max_contacts>
        </collision>
        <visual name='link_4_visual'>
          <pose>0 0.07 0.03 0 -0 0</pose>
          <geometry>
            <box>
              <size>0.06 0.14 0.06</size>
            </box>
          </geometry>
          <material>
            <script>
              <name>Gazebo/Blue</name>
              <uri>file://media/materials/scripts/gazebo.material</uri>
            </script>
          </material>
        </visual>
        <self_collide>0</self_collide>
        <enable_wind>0</enable_wind>
        <kinematic>0</kinematic>
      </link>
      <joint name='link_4_5_joint' type='revolute'>
        <pose relative_to='link_4'>0 0.175 0 0 -0 0</pose>
        <parent>link_4</parent>
        <child>link_5</child>
        <axis>
          <xyz>0 0 1</xyz>
          <limit>
            <lower>-0.785398</lower>
            <upper>0.785398</upper>
            <effort>1000</effort>
            <velocity>50</velocity>
          </limit>
          <dynamics>
            <spring_reference>0</spring_reference>
            <spring_stiffness>0</spring_stiffness>
          </dynamics>
        </axis>
      </joint>
      <link name='link_5'>
        <pose relative_to='link_4_5_joint'>0 0 0 0 -0 0</pose>
        <inertial>
          <pose>0 0.07 0.03 0 -0 0</pose>
          <mass>1</mass>
          <inertia>
            <ixx>0.00193333</ixx>
            <ixy>0</ixy>
            <ixz>0</ixz>
            <iyy>0.0006</iyy>
            <iyz>0</iyz>
            <izz>0.00193333</izz>
          </inertia>
        </inertial>
        <collision name='link_5_collision'>
          <pose>0 0.07 0.03 0 -0 0</pose>
          <geometry>
            <box>
              <size>0.06 0.14 0.06</size>
            </box>
          </geometry>
          <surface>
            <contact>
              <ode/>
            </contact>
            <friction>
              <ode/>
              <torsional>
                <ode/>
              </torsional>
            </friction>
            <bounce/>
          </surface>
          <max_contacts>10</max_contacts>
        </collision>
        <visual name='link_5_visual'>
          <pose>0 0.07 0.03 0 -0 0</pose>
          <geometry>
            <box>
              <size>0.06 0.14 0.06</size>
            </box>
          </geometry>
          <material>
            <script>
              <name>Gazebo/Green</name>
              <uri>file://media/materials/scripts/gazebo.material</uri>
            </script>
          </material>
        </visual>
        <self_collide>0</self_collide>
        <enable_wind>0</enable_wind>
        <kinematic>0</kinematic>
      </link>
      <joint name='link_5_6_joint' type='revolute'>
        <pose relative_to='link_5'>0 0.175 0 0 -0 0</pose>
        <parent>link_5</parent>
        <child>link_6</child>
        <axis>
          <xyz>0 0 1</xyz>
          <limit>
            <lower>-0.785398</lower>
            <upper>0.785398</upper>
            <effort>1000</effort>
            <velocity>50</velocity>
          </limit>
          <dynamics>
            <spring_reference>0</spring_reference>
            <spring_stiffness>0</spring_stiffness>
          </dynamics>
        </axis>
      </joint>
      <link name='link_6'>
        <pose relative_to='link_5_6_joint'>0 0 0 0 -0 0</pose>
        <inertial>
          <pose>0 0.07 0.03 0 -0 0</pose>
          <mass>1</mass>
          <inertia>
            <ixx>0.00193333</ixx>
            <ixy>0</ixy>
            <ixz>0</ixz>
            <iyy>0.0006</iyy>
            <iyz>0</iyz>
            <izz>0.00193333</izz>
          </inertia>
        </inertial>
        <collision name='link_6_collision'>
          <pose>0 0.07 0.03 0 -0 0</pose>
          <geometry>
            <box>
              <size>0.06 0.14 0.06</size>
            </box>
          </geometry>
          <surface>
            <contact>
              <ode/>
            </contact>
            <friction>
              <ode/>
              <torsional>
                <ode/>
              </torsional>
            </friction>
            <bounce/>
          </surface>
          <max_contacts>10</max_contacts>
        </collision>
        <visual name='link_6_visual'>
          <pose>0 0.07 0.03 0 -0 0</pose>
          <geometry>
            <box>
              <size>0.06 0.14 0.06</size>
            </box>
          </geometry>
          <material>
            <script>
              <name>Gazebo/Blue</name>
              <uri>file://media/materials/scripts/gazebo.material</uri>
            </script>
          </material>
        </visual>
        <self_collide>0</self_collide>
        <enable_wind>0</enable_wind>
        <kinematic>0</kinematic>
      </link>
      <joint name='link_6_7_joint' type='revolute'>
        <pose relative_to='link_6'>0 0.175 0 0 -0 0</pose>
        <parent>link_6</parent>
        <child>link_7</child>
        <axis>
          <xyz>0 0 1</xyz>
          <limit>
            <lower>-0.785398</lower>
            <upper>0.785398</upper>
            <effort>1000</effort>
            <velocity>50</velocity>
          </limit>
          <dynamics>
            <spring_reference>0</spring_reference>
            <spring_stiffness>0</spring_stiffness>
          </dynamics>
        </axis>
      </joint>
      <link name='link_7'>
        <pose relative_to='link_6_7_joint'>0 0 0 0 -0 0</pose>
        <inertial>
          <pose>0 0.07 0.03 0 -0 0</pose>
          <mass>1</mass>
          <inertia>
            <ixx>0.00193333</ixx>
            <ixy>0</ixy>
            <ixz>0</ixz>
            <iyy>0.0006</iyy>
            <iyz>0</iyz>
            <izz>0.00193333</izz>
          </inertia>
        </inertial>
        <collision name='link_7_collision'>
          <pose>0 0.07 0.03 0 -0 0</pose>
          <geometry>
            <box>
              <size>0.06 0.14 0.06</size>
            </box>
          </geometry>
          <surface>
            <contact>
              <ode/>
            </contact>
            <friction>
              <ode/>
              <torsional>
                <ode/>
              </torsional>
            </friction>
            <bounce/>
          </surface>
          <max_contacts>10</max_contacts>
        </collision>
        <visual name='link_7_visual'>
          <pose>0 0.07 0.03 0 -0 0</pose>
          <geometry>
            <box>
              <size>0.06 0.14 0.06</size>
            </box>
          </geometry>
          <material>
            <script>
              <name>Gazebo/Orange</name>
              <uri>file://media/materials/scripts/gazebo.material</uri>
            </script>
          </material>
        </visual>
        <self_collide>0</self_collide>
        <enable_wind>0</enable_wind>
        <kinematic>0</kinematic>
      </link>
      <joint name='link_7_8_joint' type='revolute'>
        <pose relative_to='link_7'>0 0.175 0 0 -0 0</pose>
        <parent>link_7</parent>
        <child>link_8</child>
        <axis>
          <xyz>0 0 1</xyz>
          <limit>
            <lower>-0.785398</lower>
            <upper>0.785398</upper>
            <effort>1000</effort>
            <velocity>50</velocity>
          </limit>
          <dynamics>
            <spring_reference>0</spring_reference>
            <spring_stiffness>0</spring_stiffness>
          </dynamics>
        </axis>
      </joint>
      <link name='link_8'>
        <pose relative_to='link_7_8_joint'>0 0 0 0 -0 0</pose>
        <inertial>
          <pose>0 0.07 0.03 0 -0 0</pose>
          <mass>1</mass>
          <inertia>
            <ixx>0.00193333</ixx>
            <ixy>0</ixy>
            <ixz>0</ixz>
            <iyy>0.0006</iyy>
            <iyz>0</iyz>
            <izz>0.00193333</izz>
          </inertia>
        </inertial>
        <collision name='link_8_collision'>
          <pose>0 0.07 0.03 0 -0 0</pose>
          <geometry>
            <box>
              <size>0.06 0.14 0.06</size>
            </box>
          </geometry>
          <surface>
            <contact>
              <ode/>
            </contact>
            <friction>
              <ode/>
              <torsional>
                <ode/>
              </torsional>
            </friction>
            <bounce/>
          </surface>
          <max_contacts>10</max_contacts>
        </collision>
        <visual name='link_8_visual'>
          <pose>0 0.07 0.03 0 -0 0</pose>
          <geometry>
            <box>
              <size>0.06 0.14 0.06</size>
            </box>
          </geometry>
          <material>
            <script>
              <name>Gazebo/Green</name>
              <uri>file://media/materials/scripts/gazebo.material</uri>
            </script>
          </material>
        </visual>
        <self_collide>0</self_collide>
        <enable_wind>0</enable_wind>
        <kinematic>0</kinematic>
      </link>
      <joint name='link_8_9_joint' type='revolute'>
        <pose relative_to='link_8'>0 0.175 0 0 -0 0</pose>
        <parent>link_8</parent>
        <child>link_9</child>
        <axis>
          <xyz>0 0 1</xyz>
          <limit>
            <lower>-0.785398</lower>
            <upper>0.785398</upper>
            <effort>1000</effort>
            <velocity>50</velocity>
          </limit>
          <dynamics>
            <spring_reference>0</spring_reference>
            <spring_stiffness>0</spring_stiffness>
          </dynamics>
        </axis>
      </joint>
      <link name='link_9'>
        <pose relative_to='link_8_9_joint'>0 0 0 0 -0 0</pose>
        <inertial>
          <pose>0 0.07 0.03 0 -0 0</pose>
          <mass>1</mass>
          <inertia>
            <ixx>0.00193333</ixx>
            <ixy>0</ixy>
            <ixz>0</ixz>
            <iyy>0.0006</iyy>
            <iyz>0</iyz>
            <izz>0.00193333</izz>
          </inertia>
        </inertial>
        <collision name='link_9_collision'>
          <pose>0 0.07 0.03 0 -0 0</pose>
          <geometry>
            <box>
              <size>0.06 0.14 0.06</size>
            </box>
          </geometry>
          <surface>
            <contact>
              <ode/>
            </contact>
            <friction>
              <ode/>
              <torsional>
                <ode/>
              </torsional>
            </friction>
            <bounce/>
          </surface>
          <max_contacts>10</max_contacts>
        </collision>
        <visual name='link_9_visual'>
          <pose>0 0.07 0.03 0 -0 0</pose>
          <geometry>
            <box>
              <size>0.06 0.14 0.06</size>
            </box>
          </geometry>
          <material>
            <script>
              <name>Gazebo/Blue</name>
              <uri>file://media/materials/scripts/gazebo.material</uri>
            </script>
          </material>
        </visual>
        <self_collide>0</self_collide>
        <enable_wind>0</enable_wind>
        <kinematic>0</kinematic>
      </link>
      <joint name='link_9_10_joint' type='revolute'>
        <pose relative_to='link_9'>0 0.175 0 0 -0 0</pose>
        <parent>link_9</parent>
        <child>link_10</child>
        <axis>
          <xyz>0 0 1</xyz>
          <limit>
            <lower>-0.785398</lower>
            <upper>0.785398</upper>
            <effort>1000</effort>
            <velocity>50</velocity>
          </limit>
          <dynamics>
            <spring_reference>0</spring_reference>
            <spring_stiffness>0</spring_stiffness>
          </dynamics>
        </axis>
      </joint>
      <link name='link_10'>
        <pose relative_to='link_9_10_joint'>0 0 0 0 -0 0</pose>
        <inertial>
          <pose>0 0.07 0.03 0 -0 0</pose>
          <mass>1</mass>
          <inertia>
            <ixx>0.00193333</ixx>
            <ixy>0</ixy>
            <ixz>0</ixz>
            <iyy>0.0006</iyy>
            <iyz>0</iyz>
            <izz>0.00193333</izz>
          </inertia>
        </inertial>
        <collision name='link_10_collision'>
          <pose>0 0.07 0.03 0 -0 0</pose>
          <geometry>
            <box>
              <size>0.06 0.14 0.06</size>
            </box>
          </geometry>
          <surface>
            <contact>
              <ode/>
            </contact>
            <friction>
              <ode/>
              <torsional>
                <ode/>
              </torsional>
            </friction>
            <bounce/>
          </surface>
          <max_contacts>10</max_contacts>
        </collision>
        <visual name='link_10_visual'>
          <pose>0 0.07 0.03 0 -0 0</pose>
          <geometry>
            <box>
              <size>0.06 0.14 0.06</size>
            </box>
          </geometry>
          <material>
            <script>
              <name>Gazebo/Orange</name>
              <uri>file://media/materials/scripts/gazebo.material</uri>
            </script>
          </material>
        </visual>
        <self_collide>0</self_collide>
        <enable_wind>0</enable_wind>
        <kinematic>0</kinematic>
      </link>
      <static>0</static>
      <plugin name='gazebo_ros_planar_move' filename='libgazebo_ros_planar_move.so'>
        <update_rate>100</update_rate>
        <publish_rate>10</publish_rate>
        <publish_odom>1</publish_odom>
        <publish_odom_tf>1</publish_odom_tf>
        <odometry_frame>odom</odometry_frame>
        <robot_base_frame>base_link</robot_base_frame>
      </plugin>
      <plugin name='gazebo_ros2_control' filename='libgazebo_ros2_control.so'>
        <parameters>/home/mohit/GITHUBRepos/snake-robot-sim/install/snake_bot/share/snake_bot/config/controllers.yaml</parameters>
      </plugin>
      <plugin name='ft_sensor' filename='libgazebo_ros_ft_sensor.so'>
        <updateRate>100.0</updateRate>
        <remapping>wrench:=joint_1</remapping>
        <joint_name>link_1_2_joint</joint_name>
        <gaussian_noise>0.01</gaussian_noise>
        <update_rate>1</update_rate>
      </plugin>
      <pose>0 0 0 0 -0 0</pose>
    </model>
    <model name='unit_cylinder'>
      <pose>0.703007 0.346173 0.5 0 -0 0</pose>
      <link name='link'>
        <inertial>
          <mass>1</mass>
          <inertia>
            <ixx>0.145833</ixx>
            <ixy>0</ixy>
            <ixz>0</ixz>
            <iyy>0.145833</iyy>
            <iyz>0</iyz>
            <izz>0.125</izz>
          </inertia>
          <pose>0 0 0 0 -0 0</pose>
        </inertial>
        <collision name='collision'>
          <geometry>
            <cylinder>
              <radius>0.500001</radius>
              <length>1.00001</length>
            </cylinder>
          </geometry>
          <max_contacts>10</max_contacts>
          <surface>
            <contact>
              <ode/>
            </contact>
            <bounce/>
            <friction>
              <torsional>
                <ode/>
              </torsional>
              <ode/>
            </friction>
          </surface>
        </collision>
        <visual name='visual'>
          <geometry>
            <cylinder>
              <radius>0.500001</radius>
              <length>1.00001</length>
            </cylinder>
          </geometry>
          <material>
            <script>
              <name>Gazebo/Grey</name>
              <uri>file://media/materials/scripts/gazebo.material</uri>
            </script>
          </material>
        </visual>
        <self_collide>0</self_collide>
        <enable_wind>0</enable_wind>
        <kinematic>0</kinematic>
      </link>
    </model>
    <model name='unit_cylinder_clone'>
      <pose>-0.077362 0.320422 0.069854 0 -0 1e-05</pose>
      <link name='link'>
        <inertial>
          <mass>1</mass>
          <inertia>
            <ixx>0.145833</ixx>
            <ixy>0</ixy>
            <ixz>0</ixz>
            <iyy>0.145833</iyy>
            <iyz>0</iyz>
            <izz>0.125</izz>
          </inertia>
          <pose>0 0 0 0 -0 0</pose>
        </inertial>
        <collision name='collision'>
          <geometry>
            <cylinder>
              <radius>0.0512893</radius>
              <length>0.139727</length>
            </cylinder>
          </geometry>
          <max_contacts>10</max_contacts>
          <surface>
            <contact>
              <ode/>
            </contact>
            <bounce/>
            <friction>
              <torsional>
                <ode/>
              </torsional>
              <ode/>
            </friction>
          </surface>
        </collision>
        <visual name='visual'>
          <geometry>
            <cylinder>
              <radius>0.0512893</radius>
              <length>0.139727</length>
            </cylinder>
          </geometry>
          <material>
            <script>
              <name>Gazebo/Grey</name>
              <uri>file://media/materials/scripts/gazebo.material</uri>
            </script>
          </material>
        </visual>
        <self_collide>0</self_collide>
        <enable_wind>0</enable_wind>
        <kinematic>0</kinematic>
      </link>
    </model>
    <model name='unit_cylinder_clone_clone'>
      <pose>0.084982 0.558164 0.069863 0 -0 0.000125</pose>
      <link name='link'>
        <inertial>
          <mass>1</mass>
          <inertia>
            <ixx>0.145833</ixx>
            <ixy>0</ixy>
            <ixz>0</ixz>
            <iyy>0.145833</iyy>
            <iyz>0</iyz>
            <izz>0.125</izz>
          </inertia>
          <pose>0 0 0 0 -0 0</pose>
        </inertial>
        <collision name='collision'>
          <geometry>
            <cylinder>
              <radius>0.0512893</radius>
              <length>0.139727</length>
            </cylinder>
          </geometry>
          <max_contacts>10</max_contacts>
          <surface>
            <contact>
              <ode/>
            </contact>
            <bounce/>
            <friction>
              <torsional>
                <ode/>
              </torsional>
              <ode/>
            </friction>
          </surface>
        </collision>
        <visual name='visual'>
          <geometry>
            <cylinder>
              <radius>0.0512893</radius>
              <length>0.139727</length>
            </cylinder>
          </geometry>
          <material>
            <script>
              <name>Gazebo/Grey</name>
              <uri>file://media/materials/scripts/gazebo.material</uri>
            </script>
          </material>
        </visual>
        <self_collide>0</self_collide>
        <enable_wind>0</enable_wind>
        <kinematic>0</kinematic>
      </link>
    </model>
    <model name='unit_cylinder_clone_clone_clone'>
      <pose>-0.082818 0.857604 0.069864 0 -0 0.000129</pose>
      <link name='link'>
        <inertial>
          <mass>1</mass>
          <inertia>
            <ixx>0.145833</ixx>
            <ixy>0</ixy>
            <ixz>0</ixz>
            <iyy>0.145833</iyy>
            <iyz>0</iyz>
            <izz>0.125</izz>
          </inertia>
          <pose>0 0 0 0 -0 0</pose>
        </inertial>
        <collision name='collision'>
          <geometry>
            <cylinder>
              <radius>0.0512893</radius>
              <length>0.139727</length>
            </cylinder>
          </geometry>
          <max_contacts>10</max_contacts>
          <surface>
            <contact>
              <ode/>
            </contact>
            <bounce/>
            <friction>
              <torsional>
                <ode/>
              </torsional>
              <ode/>
            </friction>
          </surface>
        </collision>
        <visual name='visual'>
          <geometry>
            <cylinder>
              <radius>0.0512893</radius>
              <length>0.139727</length>
            </cylinder>
          </geometry>
          <material>
            <script>
              <name>Gazebo/Grey</name>
              <uri>file://media/materials/scripts/gazebo.material</uri>
            </script>
          </material>
        </visual>
        <self_collide>0</self_collide>
        <enable_wind>0</enable_wind>
        <kinematic>0</kinematic>
      </link>
    </model>
    <model name='unit_cylinder_clone_clone_clone_clone'>
      <pose>0.085755 1.14376 0.069864 0 -0 0.000133</pose>
      <link name='link'>
        <inertial>
          <mass>1</mass>
          <inertia>
            <ixx>0.145833</ixx>
            <ixy>0</ixy>
            <ixz>0</ixz>
            <iyy>0.145833</iyy>
            <iyz>0</iyz>
            <izz>0.125</izz>
          </inertia>
          <pose>0 0 0 0 -0 0</pose>
        </inertial>
        <collision name='collision'>
          <geometry>
            <cylinder>
              <radius>0.0512893</radius>
              <length>0.139727</length>
            </cylinder>
          </geometry>
          <max_contacts>10</max_contacts>
          <surface>
            <contact>
              <ode/>
            </contact>
            <bounce/>
            <friction>
              <torsional>
                <ode/>
              </torsional>
              <ode/>
            </friction>
          </surface>
        </collision>
        <visual name='visual'>
          <geometry>
            <cylinder>
              <radius>0.0512893</radius>
              <length>0.139727</length>
            </cylinder>
          </geometry>
          <material>
            <script>
              <name>Gazebo/Grey</name>
              <uri>file://media/materials/scripts/gazebo.material</uri>
            </script>
          </material>
        </visual>
        <self_collide>0</self_collide>
        <enable_wind>0</enable_wind>
        <kinematic>0</kinematic>
      </link>
    </model>
    <model name='unit_cylinder_clone_clone_clone_clone_clone'>
      <pose>-0.084513 1.45643 0.069863 0 -0 0.000137</pose>
      <link name='link'>
        <inertial>
          <mass>1</mass>
          <inertia>
            <ixx>0.145833</ixx>
            <ixy>0</ixy>
            <ixz>0</ixz>
            <iyy>0.145833</iyy>
            <iyz>0</iyz>
            <izz>0.125</izz>
          </inertia>
          <pose>0 0 0 0 -0 0</pose>
        </inertial>
        <collision name='collision'>
          <geometry>
            <cylinder>
              <radius>0.0512893</radius>
              <length>0.139727</length>
            </cylinder>
          </geometry>
          <max_contacts>10</max_contacts>
          <surface>
            <contact>
              <ode/>
            </contact>
            <bounce/>
            <friction>
              <torsional>
                <ode/>
              </torsional>
              <ode/>
            </friction>
          </surface>
        </collision>
        <visual name='visual'>
          <geometry>
            <cylinder>
              <radius>0.0512893</radius>
              <length>0.139727</length>
            </cylinder>
          </geometry>
          <material>
            <script>
              <name>Gazebo/Grey</name>
              <uri>file://media/materials/scripts/gazebo.material</uri>
            </script>
          </material>
        </visual>
        <self_collide>0</self_collide>
        <enable_wind>0</enable_wind>
        <kinematic>0</kinematic>
      </link>
    </model>
    <model name='unit_cylinder_clone_clone_clone_clone_clone_clone'>
      <pose>0.083557 1.72166 0.069863 0 -0 0.000141</pose>
      <link name='link'>
        <inertial>
          <mass>1</mass>
          <inertia>
            <ixx>0.145833</ixx>
            <ixy>0</ixy>
            <ixz>0</ixz>
            <iyy>0.145833</iyy>
            <iyz>0</iyz>
            <izz>0.125</izz>
          </inertia>
          <pose>0 0 0 0 -0 0</pose>
        </inertial>
        <collision name='collision'>
          <geometry>
            <cylinder>
              <radius>0.0512893</radius>
              <length>0.139727</length>
            </cylinder>
          </geometry>
          <max_contacts>10</max_contacts>
          <surface>
            <contact>
              <ode/>
            </contact>
            <bounce/>
            <friction>
              <torsional>
                <ode/>
              </torsional>
              <ode/>
            </friction>
          </surface>
        </collision>
        <visual name='visual'>
          <geometry>
            <cylinder>
              <radius>0.0512893</radius>
              <length>0.139727</length>
            </cylinder>
          </geometry>
          <material>
            <script>
              <name>Gazebo/Grey</name>
              <uri>file://media/materials/scripts/gazebo.material</uri>
            </script>
          </material>
        </visual>
        <self_collide>0</self_collide>
        <enable_wind>0</enable_wind>
        <kinematic>0</kinematic>
      </link>
    </model>
    <model name='unit_cylinder_clone_0'>
      <pose>-0.083684 -0.172888 0.06986 0 -0 1.7e-05</pose>
      <link name='link'>
        <inertial>
          <mass>1</mass>
          <inertia>
            <ixx>0.145833</ixx>
            <ixy>0</ixy>
            <ixz>0</ixz>
            <iyy>0.145833</iyy>
            <iyz>0</iyz>
            <izz>0.125</izz>
          </inertia>
          <pose>0 0 0 0 -0 0</pose>
        </inertial>
        <collision name='collision'>
          <geometry>
            <cylinder>
              <radius>0.0512893</radius>
              <length>0.139727</length>
            </cylinder>
          </geometry>
          <max_contacts>10</max_contacts>
          <surface>
            <contact>
              <ode/>
            </contact>
            <bounce/>
            <friction>
              <torsional>
                <ode/>
              </torsional>
              <ode/>
            </friction>
          </surface>
        </collision>
        <visual name='visual'>
          <geometry>
            <cylinder>
              <radius>0.0512893</radius>
              <length>0.139727</length>
            </cylinder>
          </geometry>
          <material>
            <script>
              <name>Gazebo/Grey</name>
              <uri>file://media/materials/scripts/gazebo.material</uri>
            </script>
          </material>
        </visual>
        <self_collide>0</self_collide>
        <enable_wind>0</enable_wind>
        <kinematic>0</kinematic>
      </link>
    </model>
  </world>
</sdf>
